Workbook
Name CC: #REF!
Name CC: #REF!
Name CC: #REF!
Name CC: #REF!
Name CC: #REF!
Name CC: #REF!
Name CC: #REF!
Name CC: #REF!
Name CC: #REF!
Name CC: #REF!
Name GABRIEL: #REF!
Name GABRIEL: #REF!
Name GABRIEL: #REF!
Name GABRIEL: #REF!
Name GABRIEL: #REF!
Name GABRIEL: #REF!
Name GABRIEL: #REF!
Name GABRIEL: #REF!
Name GABRIEL: #REF!
Name GABRIEL: #REF!

Sheet Cliente Custos
A1: MATERIAL | C1: PREÇO DO SACO | D1: PREÇO POR KG
A2: AREIA | C2: 1100 | D2: =C2/15000 -> 0.073333333
A3: CIMENTO | C3: 37 | D3: =C3/50 -> 0.74
A4: ADITIVO | C4: 850 | D4: =C4/25 -> 34
A5: EMBALAGEM | C5: 0.6 | D5: =C5 -> 0.6
D6: =C6 -> 0
D7: =C7 -> 0
A10: PRODUÇÃO
A11: ACII | B11: QTD SACOS | C11: Produtos | D11: QTD | I11: VALOR
D12: Batida | E12: % | F12: Qtd Unit/ Saco | G12: Qtd Total Scs | H12: Qtd Total Kgs | I12: Custo Saco 25Kg | J12: Custo Kg | K12: Custo Total | L12: % CUSTO
B13: 1000 | C13: AREIA | D13: 200 | E13: =D13/D18 -> 0.79872204 | F13: =(D18*E13)/C18 -> 11.980831 | G13: =H13/25 -> 479.23323 | H13: =B13*F13 -> 11980.831 | I13: =F13*$D$2 -> 0.87859425 | J13: =(I13+I14+I15+I16+I17)/25 -> 0.18038978 | K13: =$D$2*H13 -> 878.59425 | L13: =K13/$K$18 -> 0.1948213
C14: CIMENTO | D14: 50 | E14: =D14/D18 -> 0.19968051 | F14: =(D18*E14)/C18 -> 2.9952077 | G14: =H14/25 -> 119.80831 | H14: =B13*F14 -> 2995.2077 | I14: =F14*$D$3 -> 2.2164537 | K14: =$D$3*H14 -> 2216.4537 | L14: =K14/$K$18 -> 0.491481
C15: ADITIVO | D15: 0.4 | E15: =D15/D18 -> 0.0015974441 | F15: =(D18*E15)/C18 -> 0.023961661 | G15: =H15/20 -> 1.1980831 | H15: =B13*F15 -> 23.961661 | I15: =F15*$D$4 -> 0.81469649 | K15: =$D$4*H15 -> 814.69649 | L15: =K15/$K$18 -> 0.18065247
C16: EMBALAGEM | D16: 1 | F16: 1 | G16: =H16/1 -> 1000 | H16: =F16*B13 -> 1000 | I16: =F16*$D$5 -> 0.6 | K16: =$D$5*H16 -> 600 | L16: =K16/$K$18 -> 0.13304523
G17: =H17/1 -> 0 | H17: =F17*B13 -> 0 | I17: =F17*$D$6 -> 0 | K17: =$D$6*H17 -> 0 | L17: =K17/$K$18 -> 0
B18: TOTAL | C18: =D18/15 -> 16.693333 | D18: =SUM(D13:D15) -> 250.4 | E18: =SUM(E13:E15) -> 1 | F18: =SUM(F13:F15) -> 15 | H18: =SUM(H13:H15) -> 15000 | I18: =SUM(I13:I16) -> 4.5097444 | K18: =SUM(K13:K16) -> 4509.7444

Sheet Custo ARGAMASSA
B1: MATERIAL | D1: PREÇO POR KG | E1: valor | F1: qtd
B2: AREIA | D2: =E2/F2 -> 0.081481481 | E2: 1100 | F2: 13500
B3: SILEX | D3: =E3/F3 -> 1 | E3: 1 | F3: 1
B4: CIMENTO COMUM | D4: =E4/F4 -> 0.65 | E4: 32.5 | F4: 50
B5: CIMENTO BRANCO | D5: =E5/F5 -> 1 | E5: 1 | F5: 1
B6: CELULOSICO | D6: =E6/F6 -> 33.2 | E6: 830 | F6: 25 | K6: 1000 | L6: 15000 | M6: =K6/L6 -> 0.066666667
B7: POLIMERO | D7: =E7/F7 -> 12 | E7: 300 | F7: 25
B8: PIG PRETO | D8: =E8/F8 -> 1 | E8: 1 | F8: 1 | H8: 300g
B9: PIG AMARELO | D9: =E9/F9 -> 1 | E9: 1 | F9: 1 | H9: 1kg
B10: PIG AZUL | D10: =E10/F10 -> 1 | E10: 1 | F10: 1
B11: PIG VERMELHO | D11: =E11/F11 -> 1 | E11: 1 | F11: 1
B14: PRODUÇÃO
B15: AC II | C15: QTD SACOS | D15: Produtos | E15: QTD | I15: VALOR
E16: Batida | F16: % | G16: Qtd Unit/ Saco | H16: Qtd Total | I16: Custo Saco 15Kg | J16: Custo Kg | K16: Custo Total
C17: 26000 | D17: AREIA | E17: 175 | F17: =E17/E20 -> 0.77656978 | G17: =(E20*F17)/D20 -> 11.648547 | H17: =C17*G17 -> 302862.21 | I17: =G17*$D$2 -> 0.94914084 | J17: =I20/15 -> 0.25906039 | K17: =$D$2*H17 -> 24677.662
D18: CIMENTO | E18: 50 | F18: =E18/E20 -> 0.22187708 | G18: =(E20*F18)/D20 -> 3.3281562 | H18: =C17*G18 -> 86532.061 | I18: =G18*$D$4 -> 2.1633015 | K18: =$D$4*H18 -> 56245.84
D19: CELULOSICO | E19: 0.35 | F19: =E19/E20 -> 0.0015531396 | G19: =(E20*F19)/D20 -> 0.023297093 | H19: =C17*G19 -> 605.72443 | I19: =G19*$D$6 -> 0.7734635 | K19: =$D$6*H19 -> 20110.051
C20: TOTAL | D20: =E20/15 -> 15.023333 | E20: =SUM(E17:E19) -> 225.35 | F20: =SUM(F17:F19) -> 1 | G20: =SUM(G17:G19) -> 15 | H20: =SUM(H17:H19) -> 390000 | I20: =SUM(I17:I19) -> 3.8859059 | K20: =SUM(K17:K19) -> 101033.55
M21: 450 | N21: 25 | O21: =M21/N21 -> 18
B22: PRODUÇÃO
B23: ESPECIAL | C23: QTD SACOS | D23: Produtos | E23: QTD | I23: VALOR
E24: Batida | F24: % | G24: Qtd Unit/ Saco | H24: Qtd Total | I24: Custo Saco 15Kg | J24: Custo Kg | K24: Custo Total
C25: 4000 | D25: AREIA | E25: 175 | F25: =E25/E29 -> 0.76923077 | G25: =(E29*F25)/D29 -> 11.538462 | H25: =C25*G25 -> 46153.846 | I25: =G25*$D$2 -> 0.94017094 | J25: =I29/15 -> 0.38399674 | K25: =$D$2*H25 -> 3760.6838
D26: CIMENTO | E26: 50 | F26: =E26/E29 -> 0.21978022 | G26: =(E29*F26)/D29 -> 3.2967033 | H26: =C25*G26 -> 13186.813 | I26: =G26*$D$4 -> 2.1428571 | K26: =$D$4*H26 -> 8571.4286
D27: CELULOSICO | E27: 0.5 | F27: =E27/E29 -> 0.0021978022 | G27: =(E29*F27)/D29 -> 0.032967033 | H27: =C25*G27 -> 131.86813 | I27: =G27*$D$6 -> 1.0945055 | K27: =$D$6*H27 -> 4378.022
D28: POLÍMERO | E28: 2 | F28: =E28/E29 -> 0.0087912088 | G28: =(E29*F28)/D29 -> 0.13186813 | H28: =C25*G28 -> 527.47253 | I28: =G28*$D$7 -> 1.5824176 | K28: =$D$7*H28 -> 6329.6703
C29: TOTAL | D29: =E29/15 -> 15.166667 | E29: =SUM(E25:E28) -> 227.5 | F29: =SUM(F25:F27) -> 0.99120879 | G29: =SUM(G25:G28) -> 15 | H29: =SUM(H25:H27) -> 59472.527 | I29: =SUM(I25:I28) -> 5.7599512 | K29: =SUM(K25:K28) -> 23039.805
B31: ACIII | C31: QTD SACOS | D31: Produtos | E31: QTD | I31: VALOR
E32: Batida | F32: % | G32: Qtd Unit/ Saco | H32: Qtd Total | I32: Custo Saco 15Kg | J32: Custo Kg | K32: Custo Total
C33: =E37/15 -> 68.833333 | D33: AREIA | E33: 770 | F33: =E33/E37 -> 0.74576271 | G33: =(E37*F33)/D37 -> 11.186441 | H33: =C33*G33 -> 770 | I33: =G33*$D$2 -> 0.91148776 | J33: =I37/15 -> 0.41476101 | K33: =$D$2*H33 -> 62.740741
D34: CIMENTO | E34: 250 | F34: =E34/E37 -> 0.24213075 | G34: =(E37*F34)/D37 -> 3.6319613 | H34: =C33*G34 -> 250 | I34: =G34*$D$4 -> 2.3607748 | K34: =$D$4*H34 -> 162.5
D35: CELULOSICO | E35: 2.5 | F35: =E35/E37 -> 0.0024213075 | G35: =(E37*F35)/D37 -> 0.036319613 | H35: =C33*G35 -> 2.5 | I35: =G35*$D$6 -> 1.2058111 | K35: =$D$6*H35 -> 83
D36: POLIMERO | E36: 10 | F36: =E36/E37 -> 0.00968523 | G36: =(E37*F36)/D37 -> 0.14527845 | H36: =C33*G36 -> 10 | I36: =G36*$D$7 -> 1.7433414 | K36: =$D$7*H36 -> 120
C37: TOTAL | D37: =E37/15 -> 68.833333 | E37: =SUM(E33:E36) -> 1032.5 | F37: =SUM(F33:F36) -> 1 | G37: =SUM(G33:G36) -> 15 | H37: =SUM(H33:H36) -> 1032.5 | I37: =SUM(I33:I36) -> 6.2214151 | K37: =SUM(K33:K36) -> 428.24074
B39: ACIII E | C39: QTD SACOS | D39: Produtos | E39: QTD | I39: VALOR
E40: Batida | F40: % | G40: Qtd Unit/ Saco | H40: Qtd Total | I40: Custo Saco 15Kg | J40: Custo Kg | K40: Custo Total
C41: 69 | D41: AREIA | E41: 770 | F41: =E41/E46 -> 0.74432093 | G41: =(E46*F41)/D46 -> 11.164814 | H41: =C41*G41 -> 770.37216 | I41: =G41*$D$2 -> 0.90972558 | J41: =I46/15 -> 0.43715876 | K41: =$D$2*H41 -> 62.771065
D42: CIMENTO | E42: 250 | F42: =E42/E46 -> 0.24166264 | G42: =(E46*F42)/D46 -> 3.6249396 | H42: =C41*G42 -> 250.12083 | I42: =G42*$D$4 -> 2.3562107 | K42: =$D$4*H42 -> 162.57854
D43: CELULOSICO | E43: 2.5 | F43: =E43/E46 -> 0.0024166264 | G43: =(E46*F43)/D46 -> 0.036249396 | H43: =C41*G43 -> 2.5012083 | I43: =G43*$D$6 -> 1.2034799 | K43: =$D$6*H43 -> 83.040116
D44: POLIMERO | E44: 12 | F44: =E44/E46 -> 0.011599807 | G44: =(E46*F44)/D46 -> 0.1739971 | H44: =C41*G44 -> 12.0058 | I44: =G44*$D$7 -> 2.0879652 | K44: =$D$7*H44 -> 144.0696
...

Sheet Custo Prod.
B1: MATERIAL | D1: PREÇO DO SACO | E1: PREÇO POR KG | G1: 727 | J1: kg/dolar | K1: kg/dolar + 3,25% | L1: (kg/dolar + 5%)* dolar | M1: 25kg | W1: PEDIDO 1 | AA1: PEDIDO 2 | AE1: PEDIDO 3 | AI1: PEDIDO 4 | AM1: MEDIA | AN1: MESES | AO1: PM COMPRA | AP1: PM VENDA
B2: Celulosico (MP) 25kg | D2: =G2+H2 -> 693 | E2: =D2/25 -> 27.72 | G2: 658 | H2: 35 | J2: 6.21 | K2: =J2*1.0325 -> 6.411825 | L2: =K2*5.06 -> 32.443834 | M2: =L2*25 -> 811.09586 | Q2: LUCRO DOS 80 | R2: =500-J20 -> 4.52 | S2: =R2*80 -> 361.6 | W2: venc | X2: valor total | Y2: qtd total | Z2: und | AA2: venc | AB2: valor total | AC2: qtd total | AD2: und | AE2: venc | AF2: valor total | AG2: qtd total | AH2: und | AI2: venc | AJ2: valor total | AK2: qtd total | AL2: und | AO2: 900 | AP2: 870
B3: Celugel 25kg | D3: =G3+H3 -> 214.1 | E3: =D3/25 -> 8.564 | F3: 7.3 | G3: =F3*25 -> 182.5 | H3: 31.6 | I3: 609.5 | T3: XXX | V3: 44896 | W3: 44909 | X3: 26478.5 | Y3: 30 | Z3: =X3/Y3 -> 882.61667 | AA3: 44923 | AB3: 35346.65 | AC3: 40 | AD3: =AB3/AC3 -> 883.66625 | AH3: =AF3/AG3 -> #DIV/0! | AL3: =AJ3/AK3 -> #DIV/0! | AM3: =(X3+AB3+AF3+AJ3)/(Y3+AC3+AG3+AK3) -> 883.21643 | AN3: 44531 | AO3: =1- ($AO$2/AM3) -> -0.019002784 | AP3: =$AP$2+($AP$2*AO3) -> 853.46758
B4: Fibra 20kg | D4: =G4+H4 -> 300.6 | E4: =D4/20 -> 15.03 | F4: 13.45 | G4: =F4*20 -> 269 | H4: 31.6 | J4: 526 | V4: 44927 | W4: 44942 | X4: 35166.8 | Y4: 40 | Z4: =X4/Y4 -> 879.17 | AA4: 44960 | AB4: 25980.4 | AC4: 30 | AD4: =AB4/AC4 -> 866.01333 | AH4: =AF4/AG4 -> #DIV/0! | AL4: =AJ4/AK4 -> #DIV/0! | AM4: =(X4+AB4+AF4+AJ4)/(Y4+AC4+AG4+AK4) -> 873.53143 | AN4: 44927 | AO4: =1- ($AO$2/AM4) -> -0.030300652 | AP4: =$AP$2+($AP$2*AO4) -> 843.63843
B5: Polimero (MP) 25kg | D5: =G5+H5 -> 0 | E5: =D5/25 -> 0 | V5: 44958 | W5: 44977 | X5: 33332.5 | Y5: 40 | Z5: =X5/Y5 -> 833.3125 | AA5: 44993 | AB5: 24859.4 | AC5: 30 | AD5: =AB5/AC5 -> 828.64667 | AH5: =AF5/AG5 -> #DIV/0! | AL5: =AJ5/AK5 -> #DIV/0! | AM5: =(X5+AB5+AF5+AJ5)/(Y5+AC5+AG5+AK5) -> 831.31286 | AN5: 44958 | AO5: =1- ($AO$2/AM5) -> -0.082624901 | AP5: =$AP$2+($AP$2*AO5) -> 798.11634
B6: Embalagem | D6: =G6+H6 -> 8.1 | E6: =D6 -> 8.1 | G6: 7.1 | H6: 1 | V6: 44986 | W6: 45009 | X6: 32911.9 | Y6: 40 | Z6: =X6/Y6 -> 822.7975 | AA6: 45022 | AB6: 32948.45 | AC6: 40 | AD6: =AB6/AC6 -> 823.71125 | AH6: =AF6/AG6 -> #DIV/0! | AL6: =AJ6/AK6 -> #DIV/0! | AM6: =(X6+AB6+AF6+AJ6)/(Y6+AC6+AG6+AK6) -> 823.25438 | AN6: 44986 | AO6: =1- ($AO$2/AM6) -> -0.09322225 | AP6: =$AP$2+($AP$2*AO6) -> 788.89664
B7: Adesivo | D7: =G7 -> 1.5 | E7: =D7 -> 1.5 | G7: 1.5 | V7: 45017 | X7: 33626.15 | Y7: 40 | Z7: =X7/Y7 -> 840.65375 | AD7: =AB7/AC7 -> #DIV/0! | AH7: =AF7/AG7 -> #DIV/0! | AL7: =AJ7/AK7 -> #DIV/0! | AM7: =(X7+AB7+AF7+AJ7)/(Y7+AC7+AG7+AK7) -> 840.65375 | AN7: 45017 | AO7: =1- ($AO$2/AM7) -> -0.070595355 | AP7: =$AP$2+($AP$2*AO7) -> 808.58204
B8: ??? | E8: =D8 -> 0 | V8: 45047 | W8: 45062 | X8: 24051.75 | Y8: 30 | Z8: =X8/Y8 -> 801.725 | AA8: 45079 | AB8: 30809.03 | AC8: 40 | AD8: =AB8/AC8 -> 770.22575 | AE8: 45092 | AF8: 30438.55 | AG8: 40 | AH8: =AF8/AG8 -> 760.96375 | AL8: =AJ8/AK8 -> #DIV/0! | AM8: =(X8+AB8+AF8+AJ8)/(Y8+AC8+AG8+AK8) -> 775.44845 | AN8: 45047 | AO8: =1- ($AO$2/AM8) -> -0.16061873 | AP8: =$AP$2+($AP$2*AO8) -> 730.26171
S9: =SUM(S3:S7) -> 0 | T9: TOTAL | V9: 45078 | W9: 45110 | X9: 38483.65 | Y9: 50 | Z9: =X9/Y9 -> 769.673 | AA9: 45121 | AB9: 30175.64 | AC9: 40 | AD9: =AB9/AC9 -> 754.391 | AH9: =AF9/AG9 -> #DIV/0! | AL9: =AJ9/AK9 -> #DIV/0! | AM9: =(X9+AB9+AF9+AJ9)/(Y9+AC9+AG9+AK9) -> 762.881 | AN9: 45078 | AO9: =1- ($AO$2/AM9) -> -0.17973839 | AP9: =$AP$2+($AP$2*AO9) -> 713.6276
S10: =S2-S9 -> 361.6 | V10: 45108 | W10: 45133 | X10: 29445.2 | Y10: 40 | Z10: =X10/Y10 -> 736.13 | AA10: 45135 | AB10: 7333.65 | AC10: 10 | AD10: =AB10/AC10 -> 733.365 | AE10: 45146 | AF10: 36765.05 | AG10: 50 | AH10: =AF10/AG10 -> 735.301 | AL10: =AJ10/AK10 -> #DIV/0! | AM10: =(X10+AB10+AF10+AJ10)/(Y10+AC10+AG10+AK10) -> 735.439 | AN10: 45108 | AO10: =1- ($AO$2/AM10) -> -0.22375887 | AP10: =$AP$2+($AP$2*AO10) -> 675.32978
B11: PRODUÇÃO | V11: 45139 | W11: 45163 | X11: 36774.25 | Y11: 50 | Z11: =X11/Y11 -> 735.485 | AA11: 45174 | AB11: 41710.5 | AC11: 60 | AD11: =AB11/AC11 -> 695.175 | AH11: =AF11/AG11 -> #DIV/0! | AL11: =AJ11/AK11 -> #DIV/0! | AM11: =(X11+AB11+AF11+AJ11)/(Y11+AC11+AG11+AK11) -> 713.49773 | AN11: 45139 | AO11: =1- ($AO$2/AM11) -> -0.26139154 | AP11: =$AP$2+($AP$2*AO11) -> 642.58936
B12: CELULOSICO | C12: QTD SACOS | D12: Produtos | E12: QTD | J12: VALOR | V12: 45170 | W12: 45187 | X12: 43032.7 | Y12: 60 | Z12: =X12/Y12 -> 717.21167 | AA12: 45202 | AB12: 43050.27 | AC12: 60 | AD12: =AB12/AC12 -> 717.5045 | AH12: =AF12/AG12 -> #DIV/0! | AL12: =AJ12/AK12 -> #DIV/0! | AM12: =(X12+AB12+AF12+AJ12)/(Y12+AC12+AG12+AK12) -> 717.35808 | AN12: 45170 | AO12: =1- ($AO$2/AM12) -> -0.25460355 | AP12: =$AP$2+($AP$2*AO12) -> 648.49491
E13: Batida | F13: % | G13: Qtd Unit/ Saco | H13: Qtd Total Scs | I13: Qtd Total Kgs | J13: Custo Saco 25Kg | K13: Custo Kg | L13: Custo Total | V13: 45200 | W13: 45222 | X13: 40644.4 | Y13: 60 | Z13: =X13/Y13 -> 677.40667 | AD13: =AB13/AC13 -> #DIV/0! | AH13: =AF13/AG13 -> #DIV/0! | AL13: =AJ13/AK13 -> #DIV/0! | AM13: =(X13+AB13+AF13+AJ13)/(Y13+AC13+AG13+AK13) -> 677.40667 | AN13: 45200 | AO13: =1- ($AO$2/AM13) -> -0.32859631 | AP13: =$AP$2+($AP$2*AO13) -> 584.12121
C14: 90 | D14: CELULOSICO | E14: 50 | F14: =E14/E20 -> 0.5 | G14: =(E20*F14)/D20 -> 12.5 | H14: =I14/25 -> 45 | I14: =C14*G14 -> 1125 | J14: =G14*$E$2 -> 346.5 | K14: =(J14+J15+J16+J17+J19)/25 -> 19.7592 | L14: =$E$2*I14 -> 31185 | V14: 45231 | W14: 45244 | X14: 43129.54 | Y14: 60 | Z14: =X14/Y14 -> 718.82567 | AA14: 45272 | AB14: 40828.9 | AC14: 60 | AD14: =AB14/AC14 -> 680.48167 | AH14: =AF14/AG14 -> #DIV/0! | AL14: =AJ14/AK14 -> #DIV/0! | AM14: =(X14+AB14+AF14+AJ14)/(Y14+AC14+AG14+AK14) -> 699.65367 | AN14: 45231 | AO14: =1- ($AO$2/AM14) -> -0.28635072 | AP14: =$AP$2+($AP$2*AO14) -> 620.87487
D15: CELUGEL | E15: 30 | F15: =E15/E20 -> 0.3 | G15: =(E20*F15)/D20 -> 7.5 | H15: =I15/25 -> 27 | I15: =C14*G15 -> 675 | J15: =G15*$E$3 -> 64.23 | L15: =$E$3*I15 -> 5780.7 | V15: 45261 | W15: 45282 | X15: 40549.25 | Y15: 60 | Z15: =X15/Y15 -> 675.82083 | AA15: 44934 | AB15: 38320.72 | AC15: 60 | AD15: =AB15/AC15 -> 638.67867 | AH15: =AF15/AG15 -> #DIV/0! | AL15: =AJ15/AK15 -> #DIV/0! | AM15: =(X15+AB15+AF15+AJ15)/(Y15+AC15+AG15+AK15) -> 657.24975 | AN15: 45261 | AO15: =1- ($AO$2/AM15) -> -0.36934248 | AP15: =$AP$2+($AP$2*AO15) -> 548.67205
D16: FIBRA | E16: 20 | F16: =E16/E20 -> 0.2 | G16: =(E20*F16)/D20 -> 5 | H16: =I16/20 -> 22.5 | I16: =C14*G16 -> 450 | J16: =G16*$E$4 -> 75.15 | L16: =I16*$E$4 -> 6763.5 | V16: 45292 | W16: 44957 | X16: 37679.69 | Y16: 60 | Z16: =X16/Y16 -> 627.99483 | AD16: =AB16/AC16 -> #DIV/0! | AH16: =AF16/AG16 -> #DIV/0! | AL16: =AJ16/AK16 -> #DIV/0! | AM16: =(X16+AB16+AF16+AJ16)/(Y16+AC16+AG16+AK16) -> 627.99483 | AN16: 45292 | AO16: =1- ($AO$2/AM16) -> -0.43313281 | AP16: =$AP$2+($AP$2*AO16) -> 493.17446
D17: EMBALAGEM | E17: 1 | G17: 1 | H17: =I17/1 -> 90 | I17: =G17*$C$14 -> 90 | J17: =G17*$E$6 -> 8.1 | L17: =I17*$E$6 -> 729 | AM17: =AVERAGE(AM3:AM16) -> 758.49272
D18: ADESIVO | E18: 1 | G18: 1 | H18: =I18/1 -> 90 | I18: =G18*$C$14 -> 90 | J18: =G18*$E$7 -> 1.5 | L18: =I18*$E$7 -> 135
D19: ??? | E19: 1 | G19: 1 | H19: =I19/1 -> 90 | I19: =G19*$C$14 -> 90 | J19: =G19*$E$8 -> 0 | L19: =I19*$E$8 -> 0
C20: TOTAL | D20: =E20/25 -> 4 | E20: =SUM(E14:E16) -> 100 | F20: =SUM(F14:F16) -> 1 | G20: =SUM(G14:G16) -> 25 | I20: =SUM(I14:I16) -> 2250 | J20: =SUM(J14:J19) -> 495.48 | L20: =SUM(L14:L19) -> 44593.2 | V20: 44896 | W20: 883.21643
I21: Imposto A2 2% | J21: =J20*2% -> 9.9096 | V21: 44927 | W21: 873.53143
I22: Custo Total | J22: =J20+J21 -> 505.3896 | V22: 44958 | W22: 831.31286
V23: 44986 | W23: 823.25438
V24: 45017 | W24: 840.65375
B25: PRODUÇÃO | V25: 45047 | W25: 775.44845
B26: POLIMERO | C26: QTD SACOS | D26: Produtos | E26: QTD | J26: VALOR | V26: 45078 | W26: 762.881
E27: Batida | F27: % | G27: Qtd Unit/ Saco | H27: Qtd Total Scs | I27: Qtd Total Kgs | J27: Custo Saco 15Kg | K27: Custo Kg | L27: Custo Total | V27: 45108 | W27: 735.439
C28: 12 | D28: POLIMERO | E28: 100 | F28: =E28/E32 -> 0.66666667 | G28: =(E32*F28)/D32 -> 16.666667 | H28: =I28/25 -> 8 | I28: =C28*G28 -> 200 | J28: =G28*$E$5 -> 0 | K28: =(J28+J29+J30+J31)/25 -> 2.76 | L28: =$E$5*I28 -> 0 | V28: 45139 | W28: 713.49773
D29: ARAGON | E29: 50 | F29: =E29/E32 -> 0.33333333 | G29: =(E32*F29)/D32 -> 8.3333333 | H29: =I29/25 -> 4 | I29: =C28*G29 -> 100 | J29: =G29*$E$6 -> 67.5 | L29: =$E$6*I29 -> 810 | V29: 45170 | W29: 717.35808
D30: EMBALAGEM | E30: 1 | G30: 1 | H30: =I30/1 -> 12 | I30: =G30*C28 -> 12 | J30: =G30*$E$7 -> 1.5 | L30: =I30*$E$7 -> 18 | V30: 45200 | W30: 677.40667
D31: ADESIVO | E31: 1 | G31: 1 | H31: =I31/1 -> 12 | I31: =G31*C28 -> 12 | J31: =G31*$E$8 -> 0 | L31: =I31*$E$7 -> 18 | V31: 45231 | W31: 699.65367
C32: TOTAL | D32: =E32/25 -> 6 | E32: =SUM(E28:E29) -> 150 | F32: =SUM(F28:F29) -> 1 | G32: =SUM(G28:G29) -> 25 | I32: =SUM(I28:I29) -> 300 | J32: =SUM(J28:J30) -> 69 | L32: =SUM(L28:L30) -> 828 | V32: 45261 | W32: 657.24975
V33: 45292 | W33: 627.99483
V34: MEDIA | W34: 758.49272
E36: PREÇO CECILIA | F36: CUSTO AD | G36: CUSTO TOTAL | H36: SOBRA ADM
E37: 770 | F37: 545 | G37: =F37+200 -> 745 | H37: =800-G37 -> 55 | J37: =(810-E37)/2 -> 20
E38: 780 | F38: 550 | G38: =F38+200 -> 750 | H38: =800-G38 -> 50 | J38: =(810-E38)/2 -> 15
E39: 790 | F39: 555 | G39: =F39+200 -> 755 | H39: =800-G39 -> 45 | J39: =(810-E39)/2 -> 10
E40: 800 | F40: 560 | G40: =F40+200 -> 760 | H40: =800-G40 -> 40 | J40: =(810-E40)/2 -> 5
E41: 810 | F41: 565 | G41: =F41+200 -> 765 | H41: =800-G41 -> 35 | J41: =(810-E41)/2 -> 0
...

Sheet Entrada de materiais
A1: Entrada
C3: TOTAL | D3: Mês anterior | E3: 43831 | F3: 43862 | G3: 43891 | H3: 43922 | I3: 43952 | J3: 43983 | K3: 44013 | L3: 44044 | M3: 44075 | N3: 44105 | O3: 44136 | P3: 44166
A4: PRODUTO ACABADO
A5: CELULOSICO 25kg | B5: UN | C5: =SUM(E5:AF5) -> 2180 | E5: 140 | F5: 140 | G5: 160 | H5: 140 | I5: 160 | J5: 180 | K5: 200 | L5: 220 | M5: 240 | N5: 240 | O5: 120 | P5: 240
A6: POLIMERO 25kg | B6: UN | C6: =SUM(E6:AF6) -> 0
C7: =SUM(E7:AF7) -> 0
C9: TOTAL | D9: Mês anterior | E9: 43831 | F9: 43862 | G9: 43891 | H9: 43922 | I9: 43952 | J9: 43983 | K9: 44013 | L9: 44044 | M9: 44075 | N9: 44105 | O9: 44136 | P9: 44166
A10: MATÉRIA-PRIMA
A11: Celulosico (MP) 25kg | B11: KG | C11: =SUM(D11:AI11) -> 27250 | E11: 1750 | F11: 1750 | G11: 2000 | H11: 1750 | I11: 2000 | J11: 2250 | K11: 2500 | L11: 2750 | M11: 3000 | N11: 3000 | O11: 1500 | P11: 3000
A12: Celugel 25kg | B12: KG | C12: =SUM(D12:AI12) -> 18150 | D12: 3000 | G12: 2100 | I12: 1950 | J12: 2250 | L12: 2250 | M12: 1950 | N12: 1950 | P12: 2700
A13: Fibra 20kg | B13: KG | C13: =SUM(D13:AI13) -> 12100 | D13: 2000 | G13: 1400 | I13: 1300 | J13: 1500 | L13: 1500 | M13: 1300 | N13: 1300 | P13: 1800
A14: Polimero (MP) 25kg | B14: KG | C14: =SUM(D14:AI14) -> 0
A15: Aragon 25kg | B15: KG | C15: =SUM(D15:AI15) -> 0
A16: Embalagem | B16: KG | C16: =SUM(D16:AI16) -> 2460 | D16: 410 | G16: 300 | I16: 300 | J16: 300 | L16: 300 | M16: 250 | N16: 250 | P16: 350
A17: Adesivo | C17: =SUM(D17:AI17) -> 2460 | D17: 420 | G17: 300 | I17: 300 | J17: 300 | L17: 300 | M17: 180 | N17: 310 | P17: 350

Sheet Saída de materiais
A1: Saída
C3: TOTAL | D3: 43831 | E3: 43862 | F3: 43891 | G3: 43922 | H3: 43952 | I3: 43983 | J3: 44013 | K3: 44044 | L3: 44075 | M3: 44105 | N3: 44136 | O3: 44166
A4: PRODUTO ACABADO
A5: CELULOSICO 25kg | B5: UN | C5: =SUM(D5:AH5) -> 2100 | D5: 140 | E5: 120 | F5: 149 | G5: 121 | H5: 183 | I5: 182 | J5: 222 | K5: 243 | L5: 153 | M5: 201 | N5: 196 | O5: 190
A6: POLIMERO 25kg | B6: UN | C6: =SUM(D6:AH6) -> 0
C7: =SUM(D7:AH7) -> 0
C8: =SUM(D8:AF8) -> 0
A10: MATÉRIA-PRIMA | C10: TOTAL | D10: 43831 | E10: 43862 | F10: 43891 | G10: 43922 | H10: 43952 | I10: 43983 | J10: 44013 | K10: 44044 | L10: 44075 | M10: 44105 | N10: 44136 | O10: 44166
A11: Celulosico (MP) 25kg | B11: SC | C11: =SUM(D11:AH11) -> 27250 | D11: =('Entrada de materiais'!E5*'Custo Prod.'!$G$14) -> 1750 | E11: =('Entrada de materiais'!F5*'Custo Prod.'!$G$14) -> 1750 | F11: =('Entrada de materiais'!G5*'Custo Prod.'!$G$14) -> 2000 | G11: =('Entrada de materiais'!H5*'Custo Prod.'!$G$14) -> 1750 | H11: =('Entrada de materiais'!I5*'Custo Prod.'!$G$14) -> 2000 | I11: =('Entrada de materiais'!J5*'Custo Prod.'!$G$14) -> 2250 | J11: =('Entrada de materiais'!K5*'Custo Prod.'!$G$14) -> 2500 | K11: =('Entrada de materiais'!L5*'Custo Prod.'!$G$14) -> 2750 | ... AH11: =('Entrada de materiais'!AI5*'Custo Prod.'!$G$14) -> 0
A12: Celugel 25kg | B12: SC | C12: =SUM(D12:AH12) -> 16350 | D12: =('Entrada de materiais'!E5*'Custo Prod.'!$G$15) -> 1050 | E12: =('Entrada de materiais'!F5*'Custo Prod.'!$G$15) -> 1050 | F12: =('Entrada de materiais'!G5*'Custo Prod.'!$G$15) -> 1200 | G12: =('Entrada de materiais'!H5*'Custo Prod.'!$G$15) -> 1050 | H12: =('Entrada de materiais'!I5*'Custo Prod.'!$G$15) -> 1200 | I12: =('Entrada de materiais'!J5*'Custo Prod.'!$G$15) -> 1350 | J12: =('Entrada de materiais'!K5*'Custo Prod.'!$G$15) -> 1500 | K12: =('Entrada de materiais'!L5*'Custo Prod.'!$G$15) -> 1650 | ... AH12: =('Entrada de materiais'!AI5*'Custo Prod.'!$G$15) -> 0
A13: Fibra 20kg | B13: SC | C13: =SUM(D13:AH13) -> 10900 | D13: =('Entrada de materiais'!E5*'Custo Prod.'!$G$16) -> 700 | E13: =('Entrada de materiais'!F5*'Custo Prod.'!$G$16) -> 700 | F13: =('Entrada de materiais'!G5*'Custo Prod.'!$G$16) -> 800 | G13: =('Entrada de materiais'!H5*'Custo Prod.'!$G$16) -> 700 | H13: =('Entrada de materiais'!I5*'Custo Prod.'!$G$16) -> 800 | I13: =('Entrada de materiais'!J5*'Custo Prod.'!$G$16) -> 900 | J13: =('Entrada de materiais'!K5*'Custo Prod.'!$G$16) -> 1000 | K13: =('Entrada de materiais'!L5*'Custo Prod.'!$G$16) -> 1100 | ... AH13: =('Entrada de materiais'!AI5*'Custo Prod.'!$G$16) -> 0
A14: Polimero (MP) 25kg | B14: SC | C14: =SUM(D14:AH14) -> 0 | D14: =('Entrada de materiais'!E6*'Custo Prod.'!$G$28) -> 0 | E14: =('Entrada de materiais'!F6*'Custo Prod.'!$G$28) -> 0 | F14: =('Entrada de materiais'!G6*'Custo Prod.'!$G$28) -> 0 | G14: =('Entrada de materiais'!H6*'Custo Prod.'!$G$28) -> 0 | H14: =('Entrada de materiais'!I6*'Custo Prod.'!$G$28) -> 0 | I14: =('Entrada de materiais'!J6*'Custo Prod.'!$G$28) -> 0 | J14: =('Entrada de materiais'!K6*'Custo Prod.'!$G$28) -> 0 | K14: =('Entrada de materiais'!L6*'Custo Prod.'!$G$28) -> 0 | ... AH14: =('Entrada de materiais'!AI6*'Custo Prod.'!$G$28) -> 0
A15: Aragon 25kg | B15: SC | C15: =SUM(D15:AH15) -> 0 | D15: =('Entrada de materiais'!E6*'Custo Prod.'!$G$29) -> 0 | E15: =('Entrada de materiais'!F6*'Custo Prod.'!$G$29) -> 0 | F15: =('Entrada de materiais'!G6*'Custo Prod.'!$G$29) -> 0 | G15: =('Entrada de materiais'!H6*'Custo Prod.'!$G$29) -> 0 | H15: =('Entrada de materiais'!I6*'Custo Prod.'!$G$29) -> 0 | I15: =('Entrada de materiais'!J6*'Custo Prod.'!$G$29) -> 0 | J15: =('Entrada de materiais'!K6*'Custo Prod.'!$G$29) -> 0 | K15: =('Entrada de materiais'!L6*'Custo Prod.'!$G$29) -> 0 | ... AH15: =('Entrada de materiais'!AI6*'Custo Prod.'!$G$29) -> 0
A16: Embalagem | B16: UN | C16: =SUM(D16:AH16) -> 2180 | D16: =('Entrada de materiais'!E5*'Custo Prod.'!$G$17)+('Entrada de materiais'!E6*'Custo Prod.'!$G$30) -> 140 | E16: =('Entrada de materiais'!F5*'Custo Prod.'!$G$17)+('Entrada de materiais'!F6*'Custo Prod.'!$G$30) -> 140 | F16: =('Entrada de materiais'!G5*'Custo Prod.'!$G$17)+('Entrada de materiais'!G6*'Custo Prod.'!$G$30) -> 160 | G16: =('Entrada de materiais'!H5*'Custo Prod.'!$G$17)+('Entrada de materiais'!H6*'Custo Prod.'!$G$30) -> 140 | H16: =('Entrada de materiais'!I5*'Custo Prod.'!$G$17)+('Entrada de materiais'!I6*'Custo Prod.'!$G$30) -> 160 | I16: =('Entrada de materiais'!J5*'Custo Prod.'!$G$17)+('Entrada de materiais'!J6*'Custo Prod.'!$G$30) -> 180 | J16: =('Entrada de materiais'!K5*'Custo Prod.'!$G$17)+('Entrada de materiais'!K6*'Custo Prod.'!$G$30) -> 200 | K16: =('Entrada de materiais'!L5*'Custo Prod.'!$G$17)+('Entrada de materiais'!L6*'Custo Prod.'!$G$30) -> 220 | ... AH16: =('Entrada de materiais'!AI5*'Custo Prod.'!$G$17)+('Entrada de materiais'!AI6*'Custo Prod.'!$G$30) -> 0
A17: Adesivo | B17: UN | C17: =SUM(D17:AH17) -> 2180 | D17: =('Entrada de materiais'!E5*'Custo Prod.'!$G$19)+('Entrada de materiais'!E6*'Custo Prod.'!$G$31) -> 140 | E17: =('Entrada de materiais'!F5*'Custo Prod.'!$G$19)+('Entrada de materiais'!F6*'Custo Prod.'!$G$31) -> 140 | F17: =('Entrada de materiais'!G5*'Custo Prod.'!$G$19)+('Entrada de materiais'!G6*'Custo Prod.'!$G$31) -> 160 | G17: =('Entrada de materiais'!H5*'Custo Prod.'!$G$19)+('Entrada de materiais'!H6*'Custo Prod.'!$G$31) -> 140 | H17: =('Entrada de materiais'!I5*'Custo Prod.'!$G$19)+('Entrada de materiais'!I6*'Custo Prod.'!$G$31) -> 160 | I17: =('Entrada de materiais'!J5*'Custo Prod.'!$G$19)+('Entrada de materiais'!J6*'Custo Prod.'!$G$31) -> 180 | J17: =('Entrada de materiais'!K5*'Custo Prod.'!$G$19)+('Entrada de materiais'!K6*'Custo Prod.'!$G$31) -> 200 | K17: =('Entrada de materiais'!L5*'Custo Prod.'!$G$19)+('Entrada de materiais'!L6*'Custo Prod.'!$G$31) -> 220 | ... AH17: =('Entrada de materiais'!AI5*'Custo Prod.'!$G$19)+('Entrada de materiais'!AI6*'Custo Prod.'!$G$31) -> 0

Sheet Estoque
B1: Controle de estoque | F1: =TODAY() -> 46202
B3: PRODUTOS ACABADOS
B5: Código | C5: Descrição | D5: Unid. | E5: Est Uchoa | F5: Est Conteiner | G5: CUSTO Unit | H5: CUSTO Total | I5: VENDA Unit | J5: VENDA Total
B6: 10 | C6: CELULOSICO 25kg | D6: UN | E6: 10 | F6: =SUM('Entrada de materiais'!D5:AJ5)-SUM('Saída de materiais'!D5:AH5) -> 80 | G6: ='Custo Prod.'!J20 -> 495.48 | H6: =IF(F6>0,SUM(F6*G6)," ") -> 39638.4 | I6: 840 | J6: =SUM((F6+E6)*I6) -> 75600
B7: 20 | C7: POLIMERO 25kg | D7: UN | G7: ='Custo Prod.'!J32 -> 69 | H7: =IF(F7>0,SUM(F7*G7)," ") | I7: 400 | J7: =SUM((F7+E7)*I7) -> 0
H8: =SUM(H6:H7) -> 39638.4 | J8: =SUM(J6:J7) -> 75600
B10: MATÉRIA-PRIMA
B12: Código | C12: Descrição | D12: Unid. | E12: Qtd Sacos | F12: Qtd Kg | G12: Valor Unit. | H12: Valor Total | I12: MP faz "X" Sacos
B13: 130 | C13: Celulosico (MP) 25kg | D13: SACO | E13: =F13/25 -> 0 | F13: =('Entrada de materiais'!C11-'Saída de materiais'!C11) -> 0 | G13: ='Custo Prod.'!D2 -> 693 | H13: =IF(E13>0,SUM(E13*G13)," ") | I13: =F13/12.5 -> 0
B14: 140 | C14: Celugel 25kg | D14: SACO | E14: =F14/25 -> 72 | F14: =('Entrada de materiais'!C12-'Saída de materiais'!C12) -> 1800 | G14: ='Custo Prod.'!D3 -> 214.1 | H14: =IF(E14>0,SUM(E14*G14)," ") -> 15415.2 | I14: =F14/7.5 -> 240
B15: 150 | C15: Fibra 20kg | D15: SACO | E15: =F15/20 -> 60 | F15: =('Entrada de materiais'!C13-'Saída de materiais'!C13) -> 1200 | G15: ='Custo Prod.'!D4 -> 300.6 | H15: =IF(E15>0,SUM(E15*G15)," ") -> 18036 | I15: =F15/5 -> 240
B16: 160 | C16: Polimero (MP) 25kg | D16: SACO | E16: =F16/25 -> 0 | F16: =('Entrada de materiais'!C14-'Saída de materiais'!C14) -> 0 | G16: ='Custo Prod.'!D6 -> 8.1 | H16: =IF(E16>0,SUM(E16*G16)," ")
B17: 170 | C17: Aragon 25kg | D17: SACO | E17: =F17/25 -> 0 | F17: =('Entrada de materiais'!C15-'Saída de materiais'!C15) -> 0 | G17: ='Custo Prod.'!D5 -> 0 | H17: =IF(E17>0,SUM(E17*G17)," ")
B18: 180 | C18: Embalagem | D18: UN | E18: =F18/1 -> 280 | F18: =('Entrada de materiais'!C16-'Saída de materiais'!C16) -> 280 | G18: ='Custo Prod.'!D7 -> 1.5 | H18: =IF(E18>0,SUM(E18*G18)," ") -> 420
B19: 190 | C19: Adesivos | D19: UN | E19: =F19/1 -> 280 | F19: =('Entrada de materiais'!C17-'Saída de materiais'!C17) -> 280 | G19: ='Custo Prod.'!D8 -> 0 | H19: =IF(E19>0,SUM(E19*G19)," ") -> 0
H20: =SUM(H14:H18) -> 33871.2

Sheet Caixa
A1: Resultado | B1: =(B3-B12) -> -2300 | C1: =(C3-C12) -> -11985.51 | D1: =(D3-D12) -> -39105.32 | E1: =(E3-E12) -> 25353.83 | F1: =(F3-F12) -> 18286.72 | G1: =(G3-G12) -> 43270.48 | H1: =(H3-H12) -> -41580.86 | I1: =(I3-I12) -> 33201.06 | ... N1: =(N3-N12) -> 22356.67
A2: MESES | C2: 43831 | D2: 43862 | E2: 43891 | F2: 43922 | G2: 43952 | H2: 43983 | I2: 44013 | J2: 44044 | K2: 44075 | L2: 44105 | M2: 44136 | N2: 44166
A3: Entradas | B3: =SUM(B4:B11) -> 1834560 | C3: =SUM(C4:C11) -> 189580 | D3: =SUM(D4:D11) -> 104150 | E3: =SUM(E4:E11) -> 126290 | F3: =SUM(F4:F11) -> 107660 | G3: =SUM(G4:G11) -> 169030 | H3: =SUM(H4:H11) -> 154510 | I3: =SUM(I4:I11) -> 181620 | ... AF3: =SUM(AF4:AF11) -> 0
A4: SALDO ANO 2021 | B4: =SUM(C4:AF4) -> 82250 | C4: 67650 | G4: 14600
A5: Vendas A Vista | B5: =SUM(C5:AF5) -> 1752310 | C5: ='Vendas - JAN'!G101 -> 121930 | D5: ='Vendas - FEV'!G101 -> 104150 | E5: ='Vendas - MAR'!G101 -> 126290 | F5: ='Vendas - ABR'!G101 -> 107660 | G5: ='Vendas - MAI'!G101 -> 154430 | H5: ='Vendas - JUN'!G101 -> 154510 | I5: ='Vendas - JUL'!G101 -> 181620 | J5: ='Vendas - AGO'!G101 -> 202040 | K5: ='Vendas - SET'!G101 -> 123550 | L5: ='Vendas - OUT'!G101 -> 156160 | M5: ='Vendas - NOV'!G101 -> 172610 | N5: ='Vendas - DEZ'!G101 -> 147360
A6: Saco Extra | B6: =SUM(C6:AF6) -> 0
A7: Capital | B7: =SUM(C7:AF7) -> 0
A8: Emprestimo | B8: =SUM(C8:AF8) -> 0
B9: =SUM(C9:AF9) -> 0
B10: =SUM(C10:AF10) -> 0
B11: =SUM(C11:AF11) -> 0
A12: Saidas | B12: =SUM(C12:AF12) -> 1836860 | C12: =SUM(C13+C47,C78+C62+C56+C74+C110) -> 201565.51 | D12: =SUM(,D47,D78+D62+D13+D56+D74+D110) -> 143255.32 | E12: =SUM(,E47,E78+E62+E13+E56+E74+E110) -> 100936.17 | F12: =SUM(,F47,F78+F62+F13+F56+F74+F110) -> 89373.28 | G12: =SUM(,G47,G78+G62+G13+G56+G74+G110) -> 125759.52 | H12: =SUM(,H47,H78+H62+H13+H56+H74+H110) -> 196090.86 | I12: =SUM(,I47,I78+I62+I13+I56+I74+I110) -> 148418.94 | J12: =SUM(,J47,J78+J62+J13+J56+J74+J110) -> 166561.02 | K12: =SUM(,K47,K78+K62+K13+K56+K74+K110) -> 168969.44 | ... AF12: =SUM(,AF47,AF78+AF62+AF13+AF56+AF74+AF110) -> 0
A13: Caixa | B13: =SUM(C13:AF13) -> 92703.32 | C13: =SUM(C14:C46) -> 42868.73 | D13: =SUM(D14:D46) -> 10822.5 | E13: =SUM(E14:E46) -> -5810 | F13: =SUM(F14:F46) -> 3850 | G13: =SUM(G14:G46) -> 1400 | H13: =SUM(H14:H46) -> 2000 | I13: =SUM(I14:I46) -> -4460 | J13: =SUM(J14:J46) -> 150 | ... AF13: =SUM(AF14:AF46) -> 0
A14: BB Rodrigo | B14: =SUM(C14:AF14) -> 496.29 | N14: 496.29
A15: Uchoa | B15: =SUM(C15:AF15) -> 0
A16: Dinheiro | B16: =SUM(C16:AF16) -> 910 | M16: 710 | N16: 200
A17: Paloma | B17: =SUM(C17:AF17) -> 17540 | M17: 10270 | N17: 7270
A18: Tio Fernando | B18: =SUM(C18:AF18) -> -1000 | N18: -16000 | O18: 15000
B19: =SUM(C19:AF19) -> 0
A20: Marcilio, Odilanio, Mustang Rod, Mustang Roberto, Marcio, Luis nubank, taxi Paloma, taxi Leilane, Fernadinho, Juarez, Obra, Ferradura e racao, Baxin, Feira | B20: =SUM(C20:AF20) -> 33455.99 | C20: 1030.19 | D20: 800 | E20: 2000 | F20: 3000 | G20: 1000 | H20: 1000 | I20: 540 | J20: 150 | K20: 1000 | L20: 5500 | M20: 6020.8 | N20: 550 | O20: 10000 | P20: 865
A21: Arkad, Cred Diversos, Combustivel | B21: =SUM(C21:AF21) -> -3550 | C21: -410 | D21: -3010 | E21: -130
A22: Gastos, Cha, Jacinta, Juros junior, Doação, Geladeira, salario | B22: =SUM(C22:AF22) -> 4485 | C22: 4735 | D22: 1500 | E22: 1000 | F22: 850 | G22: 400 | H22: 1000 | I22: -5000
A23: Lilian Matricula | B23: =SUM(C23:AF23) -> 88.21 | C23: 88.21
A24: rodrigo | B24: =SUM(C24:AF24) -> -36000 | C24: -36000
A25: cartao porto | B25: =SUM(C25:AF25) -> 10785.33 | C25: 10785.33
B26: =SUM(C26:AF26) -> 0
B27: =SUM(C27:AF27) -> 2.5 | D27: 2.5
A28: ??? | B28: =SUM(C28:AF28) -> 800 | C28: 800
A29: FELIPE | B29: =SUM(C29:AF29) -> 850 | C29: 850
A30: IRINEU | B30: =SUM(C30:AF30) -> 850 | C30: 850
A31: JULIO | B31: =SUM(C31:AF31) -> 4500 | C31: 4500
A32: FORTMASSA | B32: =SUM(C32:AF32) -> 1700 | C32: 850 | D32: 850
A33: GETULIO | B33: =SUM(C33:AF33) -> 2550 | C33: 2550
B34: =SUM(C34:AF34) -> 0
A35: CLAUDIO MOSSORO | B35: =SUM(C35:AF35) -> 6640 | C35: 3320 | E35: 3320
A36: LOURIMAR | B36: =SUM(C36:AF36) -> 3360 | C36: 3360
A37: CHICO PEREIRA | B37: =SUM(C37:AF37) -> 1640 | C37: 1640
A38: MULTCOLA | B38: =SUM(C38:AF38) -> 1600 | C38: 1600
A39: TODA OBRA | B39: =SUM(C39:AF39) -> 9840 | C39: 9840
A40: DEMETRIU | B40: =SUM(C40:AF40) -> 6360 | C40: 4680 | D40: 1680
...

Sheet Vendas - JAN
A1: VENDAS | B1: VENDAS | D1: =D102 -> 140
A2: DATA | B2: VENDEDOR | C2: Clientes | D2: CELULOSE | H2: POLÍMERO | K2: DESCONTO CHEQUE | L2: TOTAL | M2: PARCIAL | N2: DEVENDO | O2: CHEQUES / PAGAMENTOS A MAIS OU A MENOS | T2: Forma de Pagamento | U2: Prazo | V2: Frete CIF / FOB | W2: OBSERVAÇÃO | X2: OBSERVAÇÃO
D3: PALOMA | E3: UCHOA | F3: PREÇO | G3: TOTAL | H3: QTD | I3: PREÇO TAB | J3: TOTAL | O3: VALOR VENDA | P3: COBRAMOS % | Q3: PAGAMOS % | R3: SALDO/DEBITO CLIENTE | S3: LUCRO/PREJ JUROS
A4: 44930 | C4: CHICO PEREIRA | E4: 2 | F4: 880 | G4: =(F4*D4)+(E4*F4) -> 1760 | J4: =H4*I4 -> 0 | L4: =(J4+G4)-K4 -> 1760 | N4: =IF(M4>0,SUM(L4-M4)," ") | R4: =IF(O4>0,SUM(O4-(L4+P4))," ") | T4: A VISTA | U4: 0 | V4: FOB
A5: 44930 | C5: LUIZ PI | E5: 2 | F5: 880 | G5: =(F5*D5)+(E5*F5) -> 1760 | J5: =H5*I5 -> 0 | L5: =(J5+G5)-K5 -> 1760 | N5: =IF(M5>0,SUM(L5-M5)," ") | R5: =IF(O5>0,SUM(O5-(L5+P5))," ") | T5: A VISTA | U5: 0 | V5: FOB
A6: 44930 | C6: GETULIO | E6: 2 | F6: 880 | G6: =(F6*D6)+(E6*F6) -> 1760 | J6: =H6*I6 -> 0 | L6: =(J6+G6)-K6 -> 1760 | N6: =IF(M6>0,SUM(L6-M6)," ") | R6: =IF(O6>0,SUM(O6-(L6+P6))," ") | T6: A VISTA | U6: 0 | V6: FOB
A7: 44930 | C7: TOPMASSA | E7: 1 | F7: 900 | G7: =(F7*D7)+(E7*F7) -> 900 | J7: =H7*I7 -> 0 | L7: =(J7+G7)-K7 -> 900 | N7: =IF(M7>0,SUM(L7-M7)," ") | R7: =IF(O7>0,SUM(O7-(L7+P7))," ") | T7: A VISTA | U7: 0 | V7: FOB
A8: 44931 | C8: MULTCOLA | E8: 3 | F8: 860 | G8: =(F8*D8)+(E8*F8) -> 2580 | J8: =H8*I8 -> 0 | L8: =(J8+G8)-K8 -> 2580 | N8: =IF(M8>0,SUM(L8-M8)," ") | O8: 1400 | R8: =IF(O8>0,SUM(O8-(L8+P8))," ") -> -1180 | T8: CHEQUE/R$ | U8: 0 | V8: FOB | W8: 1100 + 300 | Y8: VALOR | Z8: QTD | AA8: =G101 -> 121930
A9: 44931 | C9: DEMETRIU | E9: 6 | F9: 860 | G9: =(F9*D9)+(E9*F9) -> 5160 | J9: =H9*I9 -> 0 | L9: =(J9+G9)-K9 -> 5160 | N9: =IF(M9>0,SUM(L9-M9)," ") | R9: =IF(O9>0,SUM(O9-(L9+P9))," ") | T9: A VISTA | U9: 0 | V9: FOB | Y9: 720 | AA9: =Y9*Z9 -> 0
A10: 44931 | C10: JOSIEL | D10: 1 | F10: 900 | G10: =(F10*D10)+(E10*F10) -> 900 | J10: =H10*I10 -> 0 | L10: =(J10+G10)-K10 -> 900 | N10: =IF(M10>0,SUM(L10-M10)," ") | R10: =IF(O10>0,SUM(O10-(L10+P10))," ") | T10: A VISTA | U10: 0 | V10: FOB | Y10: 750 | AA10: =Y10*Z10 -> 0
A11: 44931 | C11: FELIPE | D11: 1 | F11: 900 | G11: =(F11*D11)+(E11*F11) -> 900 | J11: =H11*I11 -> 0 | L11: =(J11+G11)-K11 -> 900 | N11: =IF(M11>0,SUM(L11-M11)," ") | R11: =IF(O11>0,SUM(O11-(L11+P11))," ") | T11: A VISTA | U11: 0 | V11: FOB | Y11: 780 | AA11: =Y11*Z11 -> 0
A12: 44931 | C12: FORTMASSA | D12: 1 | F12: 880 | G12: =(F12*D12)+(E12*F12) -> 880 | J12: =H12*I12 -> 0 | L12: =(J12+G12)-K12 -> 880 | N12: =IF(M12>0,SUM(L12-M12)," ") | R12: =IF(O12>0,SUM(O12-(L12+P12))," ") | T12: A VISTA | U12: 0 | V12: FOB | Y12: 800 | AA12: =Y12*Z12 -> 0
A13: 44932 | C13: CLAUDIO MOSSORO | D13: 8 | F13: 860 | G13: =(F13*D13)+(E13*F13) -> 6880 | J13: =H13*I13 -> 0 | L13: =(J13+G13)-K13 -> 6880 | N13: =IF(M13>0,SUM(L13-M13)," ") | O13: 440 | R13: =IF(O13>0,SUM(O13-(L13+P13))," ") -> -6440 | S13: =P13-Q13 -> 0 | T13: A VISTA | U13: 30 | V13: FOB | W13: QUITACAO CREDITO | AA13: =AA8-(SUM(AA9:AA12)) -> 121930
A14: 44934 | C14: ROBERTO LAGOA DO BANANA | E14: 1 | F14: 880 | G14: =(F14*D14)+(E14*F14) -> 880 | J14: =H14*I14 -> 0 | L14: =(J14+G14)-K14 -> 880 | N14: =IF(M14>0,SUM(L14-M14)," ") | R14: =IF(O14>0,SUM(O14-(L14+P14))," ")
A15: 44935 | C15: ANDRE | D15: 1 | F15: 900 | G15: =(F15*D15)+(E15*F15) -> 900 | J15: =H15*I15 -> 0 | L15: =(J15+G15)-K15 -> 900 | N15: =IF(M15>0,SUM(L15-M15)," ") | R15: =IF(O15>0,SUM(O15-(L15+P15))," ")
A16: 44935 | C16: IRINEU | D16: 1 | F16: 880 | G16: =(F16*D16)+(E16*F16) -> 880 | J16: =H16*I16 -> 0 | L16: =(J16+G16)-K16 -> 880 | N16: =IF(M16>0,SUM(L16-M16)," ") | R16: =IF(O16>0,SUM(O16-(L16+P16))," ")
A17: 44935 | C17: LOURIMAR | E17: 4 | F17: 900 | G17: =(F17*D17)+(E17*F17) -> 3600 | J17: =H17*I17 -> 0 | L17: =(J17+G17)-K17 -> 3600 | N17: =IF(M17>0,SUM(L17-M17)," ") | R17: =IF(O17>0,SUM(O17-(L17+P17))," ")
A18: 44935 | C18: FORTMASSA | D18: 1 | F18: 880 | G18: =(F18*D18)+(E18*F18) -> 880 | J18: =H18*I18 -> 0 | L18: =(J18+G18)-K18 -> 880 | N18: =IF(M18>0,SUM(L18-M18)," ") | R18: =IF(O18>0,SUM(O18-(L18+P18))," ")
A19: 44937 | C19: PAVIMARI | D19: 1 | F19: 900 | G19: =(F19*D19)+(E19*F19) -> 900 | J19: =H19*I19 -> 0 | L19: =(J19+G19)-K19 -> 900 | N19: =IF(M19>0,SUM(L19-M19)," ") | R19: =IF(O19>0,SUM(O19-(L19+P19))," ")
A20: 44937 | C20: CEARAMIX | E20: 1 | F20: 900 | G20: =(F20*D20)+(E20*F20) -> 900 | J20: =H20*I20 -> 0 | L20: =(J20+G20)-K20 -> 900 | N20: =IF(M20>0,SUM(L20-M20)," ") | R20: =IF(O20>0,SUM(O20-(L20+P20))," ")
A21: 44938 | C21: FORTMASSA | E21: 1 | F21: 880 | G21: =(F21*D21)+(E21*F21) -> 880 | J21: =H21*I21 -> 0 | L21: =(J21+G21)-K21 -> 880 | N21: =IF(M21>0,SUM(L21-M21)," ") | R21: =IF(O21>0,SUM(O21-(L21+P21))," ")
A22: 44938 | C22: AREMIX | E22: 10 | F22: 850 | G22: =(F22*D22)+(E22*F22) -> 8500 | J22: =H22*I22 -> 0 | L22: =(J22+G22)-K22 -> 8500 | N22: =IF(M22>0,SUM(L22-M22)," ") | R22: =IF(O22>0,SUM(O22-(L22+P22))," ")
A23: 44938 | C23: FELIPE | D23: 2 | F23: 900 | G23: =(F23*D23)+(E23*F23) -> 1800 | J23: =H23*I23 -> 0 | L23: =(J23+G23)-K23 -> 1800 | N23: =IF(M23>0,SUM(L23-M23)," ") | R23: =IF(O23>0,SUM(O23-(L23+P23))," ")
A24: 44938 | C24: GETULIO | D24: 2 | F24: 880 | G24: =(F24*D24)+(E24*F24) -> 1760 | J24: =H24*I24 -> 0 | L24: =(J24+G24)-K24 -> 1760 | N24: =IF(M24>0,SUM(L24-M24)," ") | R24: =IF(O24>0,SUM(O24-(L24+P24))," ")
A25: 44939 | C25: DEMETRIU | D25: 6 | F25: 860 | G25: =(F25*D25)+(E25*F25) -> 5160 | J25: =H25*I25 -> 0 | L25: =(J25+G25)-K25 -> 5160 | N25: =IF(M25>0,SUM(L25-M25)," ") | R25: =IF(O25>0,SUM(O25-(L25+P25))," ")
A26: 44939 | C26: ARG ROMA | D26: 4 | F26: 860 | G26: =(F26*D26)+(E26*F26) -> 3440 | J26: =H26*I26 -> 0 | L26: =(J26+G26)-K26 -> 3440 | N26: =IF(M26>0,SUM(L26-M26)," ") | R26: =IF(O26>0,SUM(O26-(L26+P26))," ")
A27: 44939 | C27: FORTMASSA | D27: 1 | F27: 880 | G27: =(F27*D27)+(E27*F27) -> 880 | J27: =H27*I27 -> 0 | L27: =(J27+G27)-K27 -> 880 | N27: =IF(M27>0,SUM(L27-M27)," ") | R27: =IF(O27>0,SUM(O27-(L27+P27))," ")
A28: 44942 | C28: IRINEU | D28: 1 | F28: 880 | G28: =(F28*D28)+(E28*F28) -> 880 | J28: =H28*I28 -> 0 | L28: =(J28+G28)-K28 -> 880 | N28: =IF(M28>0,SUM(L28-M28)," ") | R28: =IF(O28>0,SUM(O28-(L28+P28))," ")
A29: 44943 | C29: MEBIO | E29: 1 | F29: 870 | G29: =(F29*D29)+(E29*F29) -> 870 | J29: =H29*I29 -> 0 | L29: =(J29+G29)-K29 -> 870 | N29: =IF(M29>0,SUM(L29-M29)," ") | R29: =IF(O29>0,SUM(O29-(L29+P29))," ")
A30: 44943 | C30: CHICO PEREIRA | E30: 2 | F30: 880 | G30: =(F30*D30)+(E30*F30) -> 1760 | J30: =H30*I30 -> 0 | L30: =(J30+G30)-K30 -> 1760 | N30: =IF(M30>0,SUM(L30-M30)," ") | R30: =IF(O30>0,SUM(O30-(L30+P30))," ")
A31: 44944 | C31: FORTMASSA | D31: 1 | F31: 880 | G31: =(F31*D31)+(E31*F31) -> 880 | J31: =H31*I31 -> 0 | L31: =(J31+G31)-K31 -> 880 | N31: =IF(M31>0,SUM(L31-M31)," ") | R31: =IF(O31>0,SUM(O31-(L31+P31))," ")
A32: 44944 | C32: LOURIMAR | E32: 4 | F32: 900 | G32: =(F32*D32)+(E32*F32) -> 3600 | J32: =H32*I32 -> 0 | L32: =(J32+G32)-K32 -> 3600 | N32: =IF(M32>0,SUM(L32-M32)," ") | R32: =IF(O32>0,SUM(O32-(L32+P32))," ")
A33: 44945 | C33: MULTCOLA | E33: 4 | F33: 860 | G33: =(F33*D33)+(E33*F33) -> 3440 | J33: =H33*I33 -> 0 | L33: =(J33+G33)-K33 -> 3440 | N33: =IF(M33>0,SUM(L33-M33)," ") | R33: =IF(O33>0,SUM(O33-(L33+P33))," ")
A34: 44945 | C34: IRINEU | D34: 1 | F34: 880 | G34: =(F34*D34)+(E34*F34) -> 880 | J34: =H34*I34 -> 0 | L34: =(J34+G34)-K34 -> 880 | N34: =IF(M34>0,SUM(L34-M34)," ") | R34: =IF(O34>0,SUM(O34-(L34+P34))," ")
A35: 44946 | C35: FORTMASSA | D35: 1 | F35: 880 | G35: =(F35*D35)+(E35*F35) -> 880 | J35: =H35*I35 -> 0 | L35: =(J35+G35)-K35 -> 880 | N35: =IF(M35>0,SUM(L35-M35)," ") | R35: =IF(O35>0,SUM(O35-(L35+P35))," ")
A36: 44946 | C36: DEMETRIU | D36: 6 | F36: 860 | G36: =(F36*D36)+(E36*F36) -> 5160 | J36: =H36*I36 -> 0 | L36: =(J36+G36)-K36 -> 5160 | N36: =IF(M36>0,SUM(L36-M36)," ") | R36: =IF(O36>0,SUM(O36-(L36+P36))," ")
A37: 44946 | C37: ROBERTO LAGOA DO BANANA | D37: 1 | F37: 880 | G37: =(F37*D37)+(E37*F37) -> 880 | J37: =H37*I37 -> 0 | L37: =(J37+G37)-K37 -> 880 | N37: =IF(M37>0,SUM(L37-M37)," ") | R37: =IF(O37>0,SUM(O37-(L37+P37))," ")
A38: 44947 | C38: GETULIO | D38: 2 | F38: 880 | G38: =(F38*D38)+(E38*F38) -> 1760 | J38: =H38*I38 -> 0 | L38: =(J38+G38)-K38 -> 1760 | N38: =IF(M38>0,SUM(L38-M38)," ") | R38: =IF(O38>0,SUM(O38-(L38+P38))," ")
A39: 44949 | C39: FORTMASSA | D39: 1 | F39: 880 | G39: =(F39*D39)+(E39*F39) -> 880 | J39: =H39*I39 -> 0 | L39: =(J39+G39)-K39 -> 880 | N39: =IF(M39>0,SUM(L39-M39)," ") | R39: =IF(O39>0,SUM(O39-(L39+P39))," ")
A40: 44950 | C40: CLAUDIO MOSSORO | D40: 8 | F40: 860 | G40: =(F40*D40)+(E40*F40) -> 6880 | J40: =H40*I40 -> 0 | L40: =(J40+G40)-K40 -> 6880 | N40: =IF(M40>0,SUM(L40-M40)," ") | R40: =IF(O40>0,SUM(O40-(L40+P40))," ")
...

Sheet Vendas - FEV
A1: VENDAS | B1: VENDAS | D1: =D102 -> 120
A2: DATA | B2: VENDEDOR | C2: Clientes | D2: CELULOSE | H2: POLÍMERO | K2: DESCONTO CHEQUE | L2: TOTAL | M2: PARCIAL | N2: DEVENDO | O2: CHEQUES / PAGAMENTOS A MAIS OU A MENOS | T2: Forma de Pagamento | U2: Prazo | V2: Frete CIF / FOB | W2: OBSERVAÇÃO | X2: OBSERVAÇÃO
D3: PALOMA | E3: UCHOA | F3: PREÇO | G3: TOTAL | H3: QTD | I3: PREÇO TAB | J3: TOTAL | O3: VALOR VENDA | P3: COBRAMOS % | Q3: PAGAMOS % | R3: SALDO/DEBITO CLIENTE | S3: LUCRO/PREJ JUROS
F4: 880 | G4: =(F4*D4)+(E4*F4) -> 0 | J4: =H4*I4 -> 0 | L4: =(J4+G4)-K4 -> 0 | N4: =IF(M4>0,SUM(L4-M4)," ") | R4: =IF(O4>0,SUM(O4-(L4+P4))," ") | T4: A VISTA | U4: 0 | V4: FOB
F5: 850 | G5: =(F5*D5)+(E5*F5) -> 0 | J5: =H5*I5 -> 0 | L5: =(J5+G5)-K5 -> 0 | N5: =IF(M5>0,SUM(L5-M5)," ") | R5: =IF(O5>0,SUM(O5-(L5+P5))," ") | T5: A VISTA | U5: 0 | V5: FOB
F6: 880 | G6: =(F6*D6)+(E6*F6) -> 0 | J6: =H6*I6 -> 0 | L6: =(J6+G6)-K6 -> 0 | N6: =IF(M6>0,SUM(L6-M6)," ") | R6: =IF(O6>0,SUM(O6-(L6+P6))," ") | T6: A VISTA | U6: 0 | V6: FOB
F7: 860 | G7: =(F7*D7)+(E7*F7) -> 0 | J7: =H7*I7 -> 0 | L7: =(J7+G7)-K7 -> 0 | N7: =IF(M7>0,SUM(L7-M7)," ") | R7: =IF(O7>0,SUM(O7-(L7+P7))," ") | T7: A VISTA | U7: 0 | V7: FOB
F8: 880 | G8: =(F8*D8)+(E8*F8) -> 0 | J8: =H8*I8 -> 0 | L8: =(J8+G8)-K8 -> 0 | N8: =IF(M8>0,SUM(L8-M8)," ") | O8: 1400 | R8: =IF(O8>0,SUM(O8-(L8+P8))," ") -> 1400 | T8: CHEQUE/R$ | U8: 0 | V8: FOB | W8: 1100 + 300 | Y8: VALOR | Z8: QTD | AA8: =G101 -> 104150
A9: 44959 | C9: DEMETRIU | D9: 3 | F9: 860 | G9: =(F9*D9)+(E9*F9) -> 2580 | J9: =H9*I9 -> 0 | L9: =(J9+G9)-K9 -> 2580 | N9: =IF(M9>0,SUM(L9-M9)," ") | R9: =IF(O9>0,SUM(O9-(L9+P9))," ") | T9: A VISTA | U9: 0 | V9: FOB | Y9: 720 | AA9: =Y9*Z9 -> 0
A10: 44960 | C10: ELIEL | E10: 1 | F10: 870 | G10: =(F10*D10)+(E10*F10) -> 870 | J10: =H10*I10 -> 0 | L10: =(J10+G10)-K10 -> 870 | N10: =IF(M10>0,SUM(L10-M10)," ") | R10: =IF(O10>0,SUM(O10-(L10+P10))," ") | T10: A VISTA | U10: 0 | V10: FOB | Y10: 750 | AA10: =Y10*Z10 -> 0
A11: 44960 | C11: ROBERTO LAGOA DO BANANA | E11: 1 | F11: 880 | G11: =(F11*D11)+(E11*F11) -> 880 | J11: =H11*I11 -> 0 | L11: =(J11+G11)-K11 -> 880 | N11: =IF(M11>0,SUM(L11-M11)," ") | R11: =IF(O11>0,SUM(O11-(L11+P11))," ") | T11: A VISTA | U11: 0 | V11: FOB | Y11: 780 | AA11: =Y11*Z11 -> 0
A12: 44960 | C12: IRINEU | D12: 2 | F12: 880 | G12: =(F12*D12)+(E12*F12) -> 1760 | J12: =H12*I12 -> 0 | L12: =(J12+G12)-K12 -> 1760 | N12: =IF(M12>0,SUM(L12-M12)," ") | R12: =IF(O12>0,SUM(O12-(L12+P12))," ") | T12: A VISTA | U12: 0 | V12: FOB | Y12: 800 | AA12: =Y12*Z12 -> 0
A13: 44961 | C13: ARG ROMA | D13: 4 | F13: 860 | G13: =(F13*D13)+(E13*F13) -> 3440 | J13: =H13*I13 -> 0 | L13: =(J13+G13)-K13 -> 3440 | N13: =IF(M13>0,SUM(L13-M13)," ") | O13: 440 | R13: =IF(O13>0,SUM(O13-(L13+P13))," ") -> -3000 | S13: =P13-Q13 -> 0 | T13: A VISTA | U13: 30 | V13: FOB | W13: QUITACAO CREDITO | AA13: =AA8-(SUM(AA9:AA12)) -> 104150
A14: 44961 | C14: GETULIO | D14: 2 | F14: 880 | G14: =(F14*D14)+(E14*F14) -> 1760 | J14: =H14*I14 -> 0 | L14: =(J14+G14)-K14 -> 1760 | N14: =IF(M14>0,SUM(L14-M14)," ") | R14: =IF(O14>0,SUM(O14-(L14+P14))," ")
A15: 44963 | C15: CHICO PEREIRA | E15: 2 | F15: 880 | G15: =(F15*D15)+(E15*F15) -> 1760 | J15: =H15*I15 -> 0 | L15: =(J15+G15)-K15 -> 1760 | N15: =IF(M15>0,SUM(L15-M15)," ") | R15: =IF(O15>0,SUM(O15-(L15+P15))," ")
A16: 44964 | C16: AREMIX | E16: 10 | F16: 850 | G16: =(F16*D16)+(E16*F16) -> 8500 | J16: =H16*I16 -> 0 | L16: =(J16+G16)-K16 -> 8500 | N16: =IF(M16>0,SUM(L16-M16)," ") | R16: =IF(O16>0,SUM(O16-(L16+P16))," ")
A17: 44964 | C17: JOSIEL | E17: 1 | F17: 900 | G17: =(F17*D17)+(E17*F17) -> 900 | J17: =H17*I17 -> 0 | L17: =(J17+G17)-K17 -> 900 | N17: =IF(M17>0,SUM(L17-M17)," ") | R17: =IF(O17>0,SUM(O17-(L17+P17))," ")
A18: 44965 | C18: GETULIO | D18: 1 | F18: 880 | G18: =(F18*D18)+(E18*F18) -> 880 | J18: =H18*I18 -> 0 | L18: =(J18+G18)-K18 -> 880 | N18: =IF(M18>0,SUM(L18-M18)," ") | R18: =IF(O18>0,SUM(O18-(L18+P18))," ")
A19: 44965 | C19: CLAUDIO MOSSORO | D19: 8 | F19: 860 | G19: =(F19*D19)+(E19*F19) -> 6880 | J19: =H19*I19 -> 0 | L19: =(J19+G19)-K19 -> 6880 | N19: =IF(M19>0,SUM(L19-M19)," ") | R19: =IF(O19>0,SUM(O19-(L19+P19))," ")
A20: 44966 | C20: IRINEU | D20: 2 | F20: 880 | G20: =(F20*D20)+(E20*F20) -> 1760 | J20: =H20*I20 -> 0 | L20: =(J20+G20)-K20 -> 1760 | N20: =IF(M20>0,SUM(L20-M20)," ") | R20: =IF(O20>0,SUM(O20-(L20+P20))," ")
A21: 44966 | C21: DEMETRIU | E21: 6 | F21: 860 | G21: =(F21*D21)+(E21*F21) -> 5160 | J21: =H21*I21 -> 0 | L21: =(J21+G21)-K21 -> 5160 | N21: =IF(M21>0,SUM(L21-M21)," ") | R21: =IF(O21>0,SUM(O21-(L21+P21))," ")
A22: 44966 | C22: MULTCOLA | E22: 6 | F22: 860 | G22: =(F22*D22)+(E22*F22) -> 5160 | J22: =H22*I22 -> 0 | L22: =(J22+G22)-K22 -> 5160 | N22: =IF(M22>0,SUM(L22-M22)," ") | R22: =IF(O22>0,SUM(O22-(L22+P22))," ")
A23: 44966 | C23: TODA OBRA | E23: 3 | F23: 880 | G23: =(F23*D23)+(E23*F23) -> 2640 | J23: =H23*I23 -> 0 | L23: =(J23+G23)-K23 -> 2640 | N23: =IF(M23>0,SUM(L23-M23)," ") | R23: =IF(O23>0,SUM(O23-(L23+P23))," ")
A24: 44966 | C24: CEARAMIX | E24: 1 | F24: 900 | G24: =(F24*D24)+(E24*F24) -> 900 | J24: =H24*I24 -> 0 | L24: =(J24+G24)-K24 -> 900 | N24: =IF(M24>0,SUM(L24-M24)," ") | R24: =IF(O24>0,SUM(O24-(L24+P24))," ")
A25: 44967 | C25: ARG ROMA | D25: 4 | F25: 860 | G25: =(F25*D25)+(E25*F25) -> 3440 | J25: =H25*I25 -> 0 | L25: =(J25+G25)-K25 -> 3440 | N25: =IF(M25>0,SUM(L25-M25)," ") | R25: =IF(O25>0,SUM(O25-(L25+P25))," ")
A26: 44967 | C26: MOEBIO | D26: 1 | F26: 860 | G26: =(F26*D26)+(E26*F26) -> 860 | J26: =H26*I26 -> 0 | L26: =(J26+G26)-K26 -> 860 | N26: =IF(M26>0,SUM(L26-M26)," ") | R26: =IF(O26>0,SUM(O26-(L26+P26))," ")
A27: 44968 | C27: GETULIO | D27: 2 | F27: 880 | G27: =(F27*D27)+(E27*F27) -> 1760 | J27: =H27*I27 -> 0 | L27: =(J27+G27)-K27 -> 1760 | N27: =IF(M27>0,SUM(L27-M27)," ") | R27: =IF(O27>0,SUM(O27-(L27+P27))," ")
A28: 44968 | C28: FELIPE | D28: 1 | F28: 900 | G28: =(F28*D28)+(E28*F28) -> 900 | J28: =H28*I28 -> 0 | L28: =(J28+G28)-K28 -> 900 | N28: =IF(M28>0,SUM(L28-M28)," ") | R28: =IF(O28>0,SUM(O28-(L28+P28))," ")
A29: 44968 | C29: EVALDO SANTA INES | D29: 4 | F29: 860 | G29: =(F29*D29)+(E29*F29) -> 3440 | J29: =H29*I29 -> 0 | L29: =(J29+G29)-K29 -> 3440 | N29: =IF(M29>0,SUM(L29-M29)," ") | R29: =IF(O29>0,SUM(O29-(L29+P29))," ")
A30: 44970 | C30: LOURIMAR | E30: 4 | F30: 900 | G30: =(F30*D30)+(E30*F30) -> 3600 | J30: =H30*I30 -> 0 | L30: =(J30+G30)-K30 -> 3600 | N30: =IF(M30>0,SUM(L30-M30)," ") | R30: =IF(O30>0,SUM(O30-(L30+P30))," ")
A31: 44971 | C31: DEMETRIU | E31: 6 | F31: 860 | G31: =(F31*D31)+(E31*F31) -> 5160 | J31: =H31*I31 -> 0 | L31: =(J31+G31)-K31 -> 5160 | N31: =IF(M31>0,SUM(L31-M31)," ") | R31: =IF(O31>0,SUM(O31-(L31+P31))," ")
A32: 44971 | C32: ROBERTO LAGOA DO BANANA | E32: 2 | F32: 880 | G32: =(F32*D32)+(E32*F32) -> 1760 | J32: =H32*I32 -> 0 | L32: =(J32+G32)-K32 -> 1760 | N32: =IF(M32>0,SUM(L32-M32)," ") | R32: =IF(O32>0,SUM(O32-(L32+P32))," ")
A33: 44974 | C33: LOURIMAR | D33: 2 | F33: 900 | G33: =(F33*D33)+(E33*F33) -> 1800 | J33: =H33*I33 -> 0 | L33: =(J33+G33)-K33 -> 1800 | N33: =IF(M33>0,SUM(L33-M33)," ") | R33: =IF(O33>0,SUM(O33-(L33+P33))," ")
A34: 44975 | C34: IRINEU | D34: 1 | F34: 880 | G34: =(F34*D34)+(E34*F34) -> 880 | J34: =H34*I34 -> 0 | L34: =(J34+G34)-K34 -> 880 | N34: =IF(M34>0,SUM(L34-M34)," ") | R34: =IF(O34>0,SUM(O34-(L34+P34))," ")
A35: 44980 | C35: CHICO PEREIRA | D35: 2 | F35: 880 | G35: =(F35*D35)+(E35*F35) -> 1760 | J35: =H35*I35 -> 0 | L35: =(J35+G35)-K35 -> 1760 | N35: =IF(M35>0,SUM(L35-M35)," ") | R35: =IF(O35>0,SUM(O35-(L35+P35))," ")
A36: 44980 | C36: LOURIMAR | D36: 4 | F36: 900 | G36: =(F36*D36)+(E36*F36) -> 3600 | J36: =H36*I36 -> 0 | L36: =(J36+G36)-K36 -> 3600 | N36: =IF(M36>0,SUM(L36-M36)," ") | R36: =IF(O36>0,SUM(O36-(L36+P36))," ")
A37: 44981 | C37: GETULIO | D37: 3 | F37: 880 | G37: =(F37*D37)+(E37*F37) -> 2640 | J37: =H37*I37 -> 0 | L37: =(J37+G37)-K37 -> 2640 | N37: =IF(M37>0,SUM(L37-M37)," ") | R37: =IF(O37>0,SUM(O37-(L37+P37))," ")
A38: 44981 | C38: CLAUDIO MOSSORO | D38: 4 | F38: 860 | G38: =(F38*D38)+(E38*F38) -> 3440 | J38: =H38*I38 -> 0 | L38: =(J38+G38)-K38 -> 3440 | N38: =IF(M38>0,SUM(L38-M38)," ") | R38: =IF(O38>0,SUM(O38-(L38+P38))," ")
A39: 44981 | C39: EXPEDITO TIMON | D39: 2 | F39: 860 | G39: =(F39*D39)+(E39*F39) -> 1720 | J39: =H39*I39 -> 0 | L39: =(J39+G39)-K39 -> 1720 | N39: =IF(M39>0,SUM(L39-M39)," ") | R39: =IF(O39>0,SUM(O39-(L39+P39))," ")
A40: 44982 | C40: IRINEU | D40: 1 | F40: 880 | G40: =(F40*D40)+(E40*F40) -> 880 | J40: =H40*I40 -> 0 | L40: =(J40+G40)-K40 -> 880 | N40: =IF(M40>0,SUM(L40-M40)," ") | R40: =IF(O40>0,SUM(O40-(L40+P40))," ")
...

Sheet Vendas - MAR
A1: VENDAS | B1: VENDAS | D1: =D102 -> 145
A2: DATA | B2: VENDEDOR | C2: Clientes | D2: CELULOSE | H2: POLÍMERO | K2: DESCONTO CHEQUE | L2: TOTAL | M2: PARCIAL | N2: DEVENDO | O2: CHEQUES / PAGAMENTOS A MAIS OU A MENOS | T2: Forma de Pagamento | U2: Prazo | V2: Frete CIF / FOB | W2: OBSERVAÇÃO | X2: OBSERVAÇÃO
D3: PALOMA | E3: UCHOA | F3: PREÇO | G3: TOTAL | H3: QTD | I3: PREÇO TAB | J3: TOTAL | O3: VALOR VENDA | P3: COBRAMOS % | Q3: PAGAMOS % | R3: SALDO/DEBITO CLIENTE | S3: LUCRO/PREJ JUROS
A4: 44987 | C4: VINICIUS PACAJUS | D4: 1 | F4: 870 | G4: =(F4*D4)+(E4*F4) -> 870 | J4: =H4*I4 -> 0 | L4: =(J4+G4)-K4 -> 870 | N4: =IF(M4>0,SUM(L4-M4)," ") | R4: =IF(O4>0,SUM(O4-(L4+P4))," ") | T4: A VISTA | U4: 0 | V4: FOB
A5: 44987 | C5: GETULIO | D5: 1 | F5: 880 | G5: =(F5*D5)+(E5*F5) -> 880 | J5: =H5*I5 -> 0 | L5: =(J5+G5)-K5 -> 880 | N5: =IF(M5>0,SUM(L5-M5)," ") | R5: =IF(O5>0,SUM(O5-(L5+P5))," ") | T5: A VISTA | U5: 0 | V5: FOB
A6: 44987 | C6: LOURIMAR | D6: 4 | F6: 900 | G6: =(F6*D6)+(E6*F6) -> 3600 | J6: =H6*I6 -> 0 | L6: =(J6+G6)-K6 -> 3600 | N6: =IF(M6>0,SUM(L6-M6)," ") | R6: =IF(O6>0,SUM(O6-(L6+P6))," ") | T6: A VISTA | U6: 0 | V6: FOB
A7: 44987 | C7: ARG ROMA | D7: 4 | F7: 860 | G7: =(F7*D7)+(E7*F7) -> 3440 | J7: =H7*I7 -> 0 | L7: =(J7+G7)-K7 -> 3440 | N7: =IF(M7>0,SUM(L7-M7)," ") | R7: =IF(O7>0,SUM(O7-(L7+P7))," ") | T7: A VISTA | U7: 0 | V7: FOB
A8: 44987 | C8: CLAUDIO MOSSORO | D8: 4 | F8: 860 | G8: =(F8*D8)+(E8*F8) -> 3440 | J8: =H8*I8 -> 0 | L8: =(J8+G8)-K8 -> 3440 | N8: =IF(M8>0,SUM(L8-M8)," ") | O8: 1400 | R8: =IF(O8>0,SUM(O8-(L8+P8))," ") -> -2040 | T8: CHEQUE/R$ | U8: 0 | V8: FOB | W8: 1100 + 300 | Y8: VALOR | Z8: QTD | AA8: =G101 -> 126290
A9: 44987 | C9: IRINEU | D9: 1 | F9: 880 | G9: =(F9*D9)+(E9*F9) -> 880 | J9: =H9*I9 -> 0 | L9: =(J9+G9)-K9 -> 880 | N9: =IF(M9>0,SUM(L9-M9)," ") | R9: =IF(O9>0,SUM(O9-(L9+P9))," ") | T9: A VISTA | U9: 0 | V9: FOB | Y9: 720 | AA9: =Y9*Z9 -> 0
A10: 44988 | C10: FORTMASSA | D10: 1 | F10: 880 | G10: =(F10*D10)+(E10*F10) -> 880 | J10: =H10*I10 -> 0 | L10: =(J10+G10)-K10 -> 880 | N10: =IF(M10>0,SUM(L10-M10)," ") | R10: =IF(O10>0,SUM(O10-(L10+P10))," ") | T10: A VISTA | U10: 0 | V10: FOB | Y10: 750 | AA10: =Y10*Z10 -> 0
A11: 44989 | C11: ACARI RN | D11: 1 | F11: 860 | G11: =(F11*D11)+(E11*F11) -> 860 | J11: =H11*I11 -> 0 | L11: =(J11+G11)-K11 -> 860 | N11: =IF(M11>0,SUM(L11-M11)," ") | R11: =IF(O11>0,SUM(O11-(L11+P11))," ") | T11: A VISTA | U11: 0 | V11: FOB | Y11: 780 | AA11: =Y11*Z11 -> 0
A12: 44989 | C12: EVALDO SANTA INES | D12: 3 | F12: 860 | G12: =(F12*D12)+(E12*F12) -> 2580 | J12: =H12*I12 -> 0 | L12: =(J12+G12)-K12 -> 2580 | N12: =IF(M12>0,SUM(L12-M12)," ") | R12: =IF(O12>0,SUM(O12-(L12+P12))," ") | T12: A VISTA | U12: 0 | V12: FOB | Y12: 800 | AA12: =Y12*Z12 -> 0
F13: 900 | G13: =(F13*D13)+(E13*F13) -> 0 | J13: =H13*I13 -> 0 | L13: =(J13+G13)-K13 -> 0 | N13: =IF(M13>0,SUM(L13-M13)," ") | O13: 440 | R13: =IF(O13>0,SUM(O13-(L13+P13))," ") -> 440 | S13: =P13-Q13 -> 0 | T13: A VISTA | U13: 30 | V13: FOB | W13: QUITACAO CREDITO | AA13: =AA8-(SUM(AA9:AA12)) -> 126290
A14: 44992 | C14: DEMETRIU | E14: 6 | F14: 860 | G14: =(F14*D14)+(E14*F14) -> 5160 | J14: =H14*I14 -> 0 | L14: =(J14+G14)-K14 -> 5160 | N14: =IF(M14>0,SUM(L14-M14)," ") | R14: =IF(O14>0,SUM(O14-(L14+P14))," ")
A15: 44992 | C15: ROBERTO LAGOA DO BANANA | E15: 1 | F15: 880 | G15: =(F15*D15)+(E15*F15) -> 880 | J15: =H15*I15 -> 0 | L15: =(J15+G15)-K15 -> 880 | N15: =IF(M15>0,SUM(L15-M15)," ") | R15: =IF(O15>0,SUM(O15-(L15+P15))," ")
A16: 44992 | C16: FELIPE | D16: 2 | F16: 900 | G16: =(F16*D16)+(E16*F16) -> 1800 | J16: =H16*I16 -> 0 | L16: =(J16+G16)-K16 -> 1800 | N16: =IF(M16>0,SUM(L16-M16)," ") | R16: =IF(O16>0,SUM(O16-(L16+P16))," ")
A17: 44993 | C17: EVALDO SANTA INES | E17: 4 | F17: 860 | G17: =(F17*D17)+(E17*F17) -> 3440 | J17: =H17*I17 -> 0 | L17: =(J17+G17)-K17 -> 3440 | N17: =IF(M17>0,SUM(L17-M17)," ") | R17: =IF(O17>0,SUM(O17-(L17+P17))," ")
A18: 44993 | C18: ARG ROMA | E18: 4 | F18: 860 | G18: =(F18*D18)+(E18*F18) -> 3440 | J18: =H18*I18 -> 0 | L18: =(J18+G18)-K18 -> 3440 | N18: =IF(M18>0,SUM(L18-M18)," ") | R18: =IF(O18>0,SUM(O18-(L18+P18))," ")
A19: 44994 | C19: MULTCOLA | E19: 4 | F19: 860 | G19: =(F19*D19)+(E19*F19) -> 3440 | J19: =H19*I19 -> 0 | L19: =(J19+G19)-K19 -> 3440 | N19: =IF(M19>0,SUM(L19-M19)," ") | R19: =IF(O19>0,SUM(O19-(L19+P19))," ")
A20: 44995 | C20: MOEBIO IGUATU | D20: 1 | F20: 860 | G20: =(F20*D20)+(E20*F20) -> 860 | J20: =H20*I20 -> 0 | L20: =(J20+G20)-K20 -> 860 | N20: =IF(M20>0,SUM(L20-M20)," ") | R20: =IF(O20>0,SUM(O20-(L20+P20))," ")
A21: 44995 | C21: LOURIMAR | D21: 4 | F21: 900 | G21: =(F21*D21)+(E21*F21) -> 3600 | J21: =H21*I21 -> 0 | L21: =(J21+G21)-K21 -> 3600 | N21: =IF(M21>0,SUM(L21-M21)," ") | R21: =IF(O21>0,SUM(O21-(L21+P21))," ")
A22: 44995 | C22: CLAUDIO MOSSORO | D22: 8 | F22: 860 | G22: =(F22*D22)+(E22*F22) -> 6880 | J22: =H22*I22 -> 0 | L22: =(J22+G22)-K22 -> 6880 | N22: =IF(M22>0,SUM(L22-M22)," ") | R22: =IF(O22>0,SUM(O22-(L22+P22))," ")
A23: 44996 | C23: GETULIO | D23: 2 | F23: 880 | G23: =(F23*D23)+(E23*F23) -> 1760 | J23: =H23*I23 -> 0 | L23: =(J23+G23)-K23 -> 1760 | N23: =IF(M23>0,SUM(L23-M23)," ") | R23: =IF(O23>0,SUM(O23-(L23+P23))," ")
A24: 44996 | C24: EVALDO SANTA INES | D24: 4 | F24: 860 | G24: =(F24*D24)+(E24*F24) -> 3440 | J24: =H24*I24 -> 0 | L24: =(J24+G24)-K24 -> 3440 | N24: =IF(M24>0,SUM(L24-M24)," ") | R24: =IF(O24>0,SUM(O24-(L24+P24))," ")
A25: 44998 | C25: DEMETRIU | E25: 6 | F25: 860 | G25: =(F25*D25)+(E25*F25) -> 5160 | J25: =H25*I25 -> 0 | L25: =(J25+G25)-K25 -> 5160 | N25: =IF(M25>0,SUM(L25-M25)," ") | R25: =IF(O25>0,SUM(O25-(L25+P25))," ")
A26: 44998 | C26: CHICO PEREIRA | E26: 2 | F26: 880 | G26: =(F26*D26)+(E26*F26) -> 1760 | J26: =H26*I26 -> 0 | L26: =(J26+G26)-K26 -> 1760 | N26: =IF(M26>0,SUM(L26-M26)," ") | R26: =IF(O26>0,SUM(O26-(L26+P26))," ")
A27: 44999 | C27: FELIPE | D27: 1 | F27: 900 | G27: =(F27*D27)+(E27*F27) -> 900 | J27: =H27*I27 -> 0 | L27: =(J27+G27)-K27 -> 900 | N27: =IF(M27>0,SUM(L27-M27)," ") | R27: =IF(O27>0,SUM(O27-(L27+P27))," ")
A28: 44999 | C28: JOSIEL | D28: 1 | F28: 900 | G28: =(F28*D28)+(E28*F28) -> 900 | J28: =H28*I28 -> 0 | L28: =(J28+G28)-K28 -> 900 | N28: =IF(M28>0,SUM(L28-M28)," ") | R28: =IF(O28>0,SUM(O28-(L28+P28))," ")
A29: 45000 | C29: EVALDO SANTA INES | D29: 4 | F29: 860 | G29: =(F29*D29)+(E29*F29) -> 3440 | J29: =H29*I29 -> 0 | L29: =(J29+G29)-K29 -> 3440 | N29: =IF(M29>0,SUM(L29-M29)," ") | R29: =IF(O29>0,SUM(O29-(L29+P29))," ")
A30: 45000 | C30: GETULIO | D30: 1 | F30: 880 | G30: =(F30*D30)+(E30*F30) -> 880 | J30: =H30*I30 -> 0 | L30: =(J30+G30)-K30 -> 880 | N30: =IF(M30>0,SUM(L30-M30)," ") | R30: =IF(O30>0,SUM(O30-(L30+P30))," ")
A31: 45001 | C31: IRINEU | D31: 1 | F31: 880 | G31: =(F31*D31)+(E31*F31) -> 880 | J31: =H31*I31 -> 0 | L31: =(J31+G31)-K31 -> 880 | N31: =IF(M31>0,SUM(L31-M31)," ") | R31: =IF(O31>0,SUM(O31-(L31+P31))," ")
A32: 45001 | C32: MASSA FIXA | D32: 2 | F32: 880 | G32: =(F32*D32)+(E32*F32) -> 1760 | J32: =H32*I32 -> 0 | L32: =(J32+G32)-K32 -> 1760 | N32: =IF(M32>0,SUM(L32-M32)," ") | R32: =IF(O32>0,SUM(O32-(L32+P32))," ")
A33: 45002 | C33: LOURIMAR | E33: 4 | F33: 900 | G33: =(F33*D33)+(E33*F33) -> 3600 | J33: =H33*I33 -> 0 | L33: =(J33+G33)-K33 -> 3600 | N33: =IF(M33>0,SUM(L33-M33)," ") | R33: =IF(O33>0,SUM(O33-(L33+P33))," ")
A34: 45003 | C34: EVALDO SANTA INES | D34: 4 | F34: 860 | G34: =(F34*D34)+(E34*F34) -> 3440 | J34: =H34*I34 -> 0 | L34: =(J34+G34)-K34 -> 3440 | N34: =IF(M34>0,SUM(L34-M34)," ") | R34: =IF(O34>0,SUM(O34-(L34+P34))," ")
A35: 45003 | C35: ARG ROMA | D35: 3 | F35: 860 | G35: =(F35*D35)+(E35*F35) -> 2580 | J35: =H35*I35 -> 0 | L35: =(J35+G35)-K35 -> 2580 | N35: =IF(M35>0,SUM(L35-M35)," ") | R35: =IF(O35>0,SUM(O35-(L35+P35))," ")
A36: 45006 | C36: DEMETRIU | E36: 6 | F36: 860 | G36: =(F36*D36)+(E36*F36) -> 5160 | J36: =H36*I36 -> 0 | L36: =(J36+G36)-K36 -> 5160 | N36: =IF(M36>0,SUM(L36-M36)," ") | R36: =IF(O36>0,SUM(O36-(L36+P36))," ")
A37: 45006 | C37: FELIPE | D37: 2 | F37: 900 | G37: =(F37*D37)+(E37*F37) -> 1800 | J37: =H37*I37 -> 0 | L37: =(J37+G37)-K37 -> 1800 | N37: =IF(M37>0,SUM(L37-M37)," ") | R37: =IF(O37>0,SUM(O37-(L37+P37))," ")
A38: 45006 | C38: MASSA FIXA | E38: 2 | F38: 880 | G38: =(F38*D38)+(E38*F38) -> 1760 | J38: =H38*I38 -> 0 | L38: =(J38+G38)-K38 -> 1760 | N38: =IF(M38>0,SUM(L38-M38)," ") | R38: =IF(O38>0,SUM(O38-(L38+P38))," ")
F39: 870 | G39: =(F39*D39)+(E39*F39) -> 0 | J39: =H39*I39 -> 0 | L39: =(J39+G39)-K39 -> 0 | N39: =IF(M39>0,SUM(L39-M39)," ") | R39: =IF(O39>0,SUM(O39-(L39+P39))," ")
A40: 45007 | C40: GETULIO | D40: 3 | F40: 880 | G40: =(F40*D40)+(E40*F40) -> 2640 | J40: =H40*I40 -> 0 | L40: =(J40+G40)-K40 -> 2640 | N40: =IF(M40>0,SUM(L40-M40)," ") | R40: =IF(O40>0,SUM(O40-(L40+P40))," ")
...

Sheet Vendas - ABR
A1: VENDAS | B1: VENDAS | D1: =D102 -> 125
A2: DATA | B2: VENDEDOR | C2: Clientes - 35 | D2: CELULOSE | H2: POLÍMERO | K2: DESCONTO CHEQUE | L2: TOTAL | M2: PARCIAL | N2: DEVENDO | O2: CHEQUES / PAGAMENTOS A MAIS OU A MENOS | T2: Forma de Pagamento | U2: Prazo | V2: Frete CIF / FOB | W2: OBSERVAÇÃO | X2: OBSERVAÇÃO
D3: PALOMA | E3: UCHOA | F3: PREÇO | G3: TOTAL | H3: QTD | I3: PREÇO TAB | J3: TOTAL | O3: VALOR VENDA | P3: COBRAMOS % | Q3: PAGAMOS % | R3: SALDO/DEBITO CLIENTE | S3: LUCRO/PREJ JUROS
A4: 45019 | C4: DEMETRIU | D4: 4 | F4: 840 | G4: =(F4*D4)+(E4*F4) -> 3360 | J4: =H4*I4 -> 0 | L4: =(J4+G4)-K4 -> 3360 | N4: =IF(M4>0,SUM(L4-M4)," ") | R4: =IF(O4>0,SUM(O4-(L4+P4))," ") | T4: A VISTA | U4: 0 | V4: FOB
A5: 45020 | C5: GETULIO | D5: 1 | F5: 880 | G5: =(F5*D5)+(E5*F5) -> 880 | J5: =H5*I5 -> 0 | L5: =(J5+G5)-K5 -> 880 | N5: =IF(M5>0,SUM(L5-M5)," ") | R5: =IF(O5>0,SUM(O5-(L5+P5))," ") | T5: A VISTA | U5: 0 | V5: FOB
A6: 45021 | C6: IRINEU | D6: 1 | F6: 880 | G6: =(F6*D6)+(E6*F6) -> 880 | J6: =H6*I6 -> 0 | L6: =(J6+G6)-K6 -> 880 | N6: =IF(M6>0,SUM(L6-M6)," ") | R6: =IF(O6>0,SUM(O6-(L6+P6))," ") | T6: A VISTA | U6: 0 | V6: FOB
F7: 880 | G7: =(F7*D7)+(E7*F7) -> 0 | J7: =H7*I7 -> 0 | L7: =(J7+G7)-K7 -> 0 | N7: =IF(M7>0,SUM(L7-M7)," ") | R7: =IF(O7>0,SUM(O7-(L7+P7))," ") | T7: A VISTA | U7: 0 | V7: FOB
A8: 45021 | C8: EVALDO SANTA INES | D8: 6 | F8: 860 | G8: =(F8*D8)+(E8*F8) -> 5160 | J8: =H8*I8 -> 0 | L8: =(J8+G8)-K8 -> 5160 | N8: =IF(M8>0,SUM(L8-M8)," ") | O8: 1400 | R8: =IF(O8>0,SUM(O8-(L8+P8))," ") -> -3760 | T8: CHEQUE/R$ | U8: 0 | V8: FOB | W8: 1100 + 300 | Y8: VALOR | Z8: QTD | AA8: =G101 -> 107660
A9: 45022 | C9: CHICO PEREIRA | E9: 2 | F9: 880 | G9: =(F9*D9)+(E9*F9) -> 1760 | J9: =H9*I9 -> 0 | L9: =(J9+G9)-K9 -> 1760 | N9: =IF(M9>0,SUM(L9-M9)," ") | R9: =IF(O9>0,SUM(O9-(L9+P9))," ") | T9: A VISTA | U9: 0 | V9: FOB | Y9: 720 | AA9: =Y9*Z9 -> 0
A10: 45027 | C10: MOEBIO | D10: 1 | F10: 860 | G10: =(F10*D10)+(E10*F10) -> 860 | J10: =H10*I10 -> 0 | L10: =(J10+G10)-K10 -> 860 | N10: =IF(M10>0,SUM(L10-M10)," ") | R10: =IF(O10>0,SUM(O10-(L10+P10))," ") | T10: A VISTA | U10: 0 | V10: FOB | Y10: 750 | AA10: =Y10*Z10 -> 0
A11: 45027 | C11: FELIPE | D11: 1 | F11: 900 | G11: =(F11*D11)+(E11*F11) -> 900 | J11: =H11*I11 -> 0 | L11: =(J11+G11)-K11 -> 900 | N11: =IF(M11>0,SUM(L11-M11)," ") | R11: =IF(O11>0,SUM(O11-(L11+P11))," ") | T11: A VISTA | U11: 0 | V11: FOB | Y11: 780 | AA11: =Y11*Z11 -> 0
A12: 45027 | C12: JOSIEL | D12: 1 | F12: 900 | G12: =(F12*D12)+(E12*F12) -> 900 | J12: =H12*I12 -> 0 | L12: =(J12+G12)-K12 -> 900 | N12: =IF(M12>0,SUM(L12-M12)," ") | R12: =IF(O12>0,SUM(O12-(L12+P12))," ") | T12: A VISTA | U12: 0 | V12: FOB | Y12: 800 | AA12: =Y12*Z12 -> 0
